[2021-03-13 02:50:57,281][Thread-1:11400][task_id:django.request][log.py:230][ERROR][Internal Server Error: /analysis/news/latest/AMAZ]
Traceback (most recent call last):
  File "D:\Projects\Stock_Trend_Analysis_APP\stock-trend-ana-admin\venv\lib\site-packages\django\core\handlers\exception.py", line 47, in inner
    response = get_response(request)
  File "D:\Projects\Stock_Trend_Analysis_APP\stock-trend-ana-admin\venv\lib\site-packages\django\core\handlers\base.py", line 181, in _get_response
    response = wrapped_callback(request, *callback_args, **callback_kwargs)
  File "D:\Projects\Stock_Trend_Analysis_APP\stock-trend-ana-admin\sta_admin\analysis\views.py", line 30, in get_latest_news
    logger.log("parameter stock is: ----> ", stock)
  File "C:\Users\AARON-PREDATOR\AppData\Local\Programs\Python\Python36\lib\logging\__init__.py", line 1369, in log
    raise TypeError("level must be an integer")
TypeError: level must be an integer
[2021-03-13 02:50:57,283][Thread-1:11400][task_id:django.server][basehttp.py:157][ERROR]["GET /analysis/news/latest/AMAZ HTTP/1.1" 500 80145]
[2021-03-13 03:05:37,697][Thread-1:10088][task_id:django.request][log.py:230][ERROR][Internal Server Error: /analysis/news/latest/AMAZ]
Traceback (most recent call last):
  File "D:\Projects\Stock_Trend_Analysis_APP\stock-trend-ana-admin\venv\lib\site-packages\django\core\handlers\exception.py", line 47, in inner
    response = get_response(request)
  File "D:\Projects\Stock_Trend_Analysis_APP\stock-trend-ana-admin\venv\lib\site-packages\django\core\handlers\base.py", line 181, in _get_response
    response = wrapped_callback(request, *callback_args, **callback_kwargs)
  File "D:\Projects\Stock_Trend_Analysis_APP\stock-trend-ana-admin\sta_admin\analysis\views.py", line 32, in get_latest_news
    a, b = crawl_news(stock)
  File "D:\Projects\Stock_Trend_Analysis_APP\stock-trend-ana-admin\sta_admin\common\NewCollector.py", line 20, in crawl_news
    html_content = BeautifulSoup(urlopen(req))
  File "C:\Users\AARON-PREDATOR\AppData\Local\Programs\Python\Python36\lib\urllib\request.py", line 223, in urlopen
    return opener.open(url, data, timeout)
  File "C:\Users\AARON-PREDATOR\AppData\Local\Programs\Python\Python36\lib\urllib\request.py", line 532, in open
    response = meth(req, response)
  File "C:\Users\AARON-PREDATOR\AppData\Local\Programs\Python\Python36\lib\urllib\request.py", line 642, in http_response
    'http', request, response, code, msg, hdrs)
  File "C:\Users\AARON-PREDATOR\AppData\Local\Programs\Python\Python36\lib\urllib\request.py", line 570, in error
    return self._call_chain(*args)
  File "C:\Users\AARON-PREDATOR\AppData\Local\Programs\Python\Python36\lib\urllib\request.py", line 504, in _call_chain
    result = func(*args)
  File "C:\Users\AARON-PREDATOR\AppData\Local\Programs\Python\Python36\lib\urllib\request.py", line 650, in http_error_default
    raise HTTPError(req.full_url, code, msg, hdrs, fp)
urllib.error.HTTPError: HTTP Error 404: Not Found
[2021-03-13 03:05:37,698][Thread-1:10088][task_id:django.server][basehttp.py:157][ERROR]["GET /analysis/news/latest/AMAZ HTTP/1.1" 500 111128]
[2021-03-13 04:33:48,416][Thread-6:17952][task_id:django.request][log.py:230][ERROR][Internal Server Error: /analysis/news/latest/AMAZ]
Traceback (most recent call last):
  File "D:\Projects\Stock_Trend_Analysis_APP\stock-trend-ana-admin\venv\lib\site-packages\django\core\handlers\exception.py", line 47, in inner
    response = get_response(request)
  File "D:\Projects\Stock_Trend_Analysis_APP\stock-trend-ana-admin\venv\lib\site-packages\django\core\handlers\base.py", line 181, in _get_response
    response = wrapped_callback(request, *callback_args, **callback_kwargs)
  File "D:\Projects\Stock_Trend_Analysis_APP\stock-trend-ana-admin\sta_admin\analysis\views.py", line 32, in get_latest_news
    a, b = crawl_news(stock)
  File "D:\Projects\Stock_Trend_Analysis_APP\stock-trend-ana-admin\sta_admin\common\NewCollector.py", line 21, in crawl_news
    response = requests.get(url=url, headers=headers)
  File "D:\Projects\Stock_Trend_Analysis_APP\stock-trend-ana-admin\venv\lib\site-packages\requests\api.py", line 76, in get
    return request('get', url, params=params, **kwargs)
  File "D:\Projects\Stock_Trend_Analysis_APP\stock-trend-ana-admin\venv\lib\site-packages\requests\api.py", line 61, in request
    return session.request(method=method, url=url, **kwargs)
  File "D:\Projects\Stock_Trend_Analysis_APP\stock-trend-ana-admin\venv\lib\site-packages\requests\sessions.py", line 542, in request
    resp = self.send(prep, **send_kwargs)
  File "D:\Projects\Stock_Trend_Analysis_APP\stock-trend-ana-admin\venv\lib\site-packages\requests\sessions.py", line 649, in send
    adapter = self.get_adapter(url=request.url)
  File "D:\Projects\Stock_Trend_Analysis_APP\stock-trend-ana-admin\venv\lib\site-packages\requests\sessions.py", line 742, in get_adapter
    raise InvalidSchema("No connection adapters were found for {!r}".format(url))
requests.exceptions.InvalidSchema: No connection adapters were found for 'Ahttps://finviz.com/quote.ashx?t=Mhttps://finviz.com/quote.ashx?t=Ahttps://finviz.com/quote.ashx?t=Z'
[2021-03-13 04:33:48,419][Thread-6:17952][task_id:django.server][basehttp.py:157][ERROR]["GET /analysis/news/latest/AMAZ HTTP/1.1" 500 108898]
[2021-03-13 04:34:34,868][Thread-6:10100][task_id:django.request][log.py:230][ERROR][Internal Server Error: /analysis/news/latest/AMAZ]
Traceback (most recent call last):
  File "D:\Projects\Stock_Trend_Analysis_APP\stock-trend-ana-admin\venv\lib\site-packages\django\core\handlers\exception.py", line 47, in inner
    response = get_response(request)
  File "D:\Projects\Stock_Trend_Analysis_APP\stock-trend-ana-admin\venv\lib\site-packages\django\core\handlers\base.py", line 181, in _get_response
    response = wrapped_callback(request, *callback_args, **callback_kwargs)
  File "D:\Projects\Stock_Trend_Analysis_APP\stock-trend-ana-admin\sta_admin\analysis\views.py", line 32, in get_latest_news
    a, b = crawl_news(stock)
TypeError: 'NoneType' object is not iterable
[2021-03-13 04:34:34,870][Thread-6:10100][task_id:django.server][basehttp.py:157][ERROR]["GET /analysis/news/latest/AMAZ HTTP/1.1" 500 78605]
[2021-03-13 05:24:02,693][Thread-1:14648][task_id:django.request][log.py:230][ERROR][Internal Server Error: /analysis/news/latest/AMZN]
Traceback (most recent call last):
  File "D:\Projects\Stock_Trend_Analysis_APP\stock-trend-ana-admin\venv\lib\site-packages\django\core\handlers\exception.py", line 47, in inner
    response = get_response(request)
  File "D:\Projects\Stock_Trend_Analysis_APP\stock-trend-ana-admin\venv\lib\site-packages\django\core\handlers\base.py", line 181, in _get_response
    response = wrapped_callback(request, *callback_args, **callback_kwargs)
  File "D:\Projects\Stock_Trend_Analysis_APP\stock-trend-ana-admin\sta_admin\analysis\views.py", line 35, in get_latest_news
    news = generate_score(raw_news)
TypeError: generate_score() missing 1 required positional argument: 'key'
[2021-03-13 05:24:02,694][Thread-1:14648][task_id:django.server][basehttp.py:157][ERROR]["GET /analysis/news/latest/AMZN HTTP/1.1" 500 77773]
[2021-03-13 05:24:23,611][Thread-1:6472][task_id:django.request][log.py:230][ERROR][Internal Server Error: /analysis/news/latest/AMZN]
Traceback (most recent call last):
  File "D:\Projects\Stock_Trend_Analysis_APP\stock-trend-ana-admin\venv\lib\site-packages\django\core\handlers\exception.py", line 47, in inner
    response = get_response(request)
  File "D:\Projects\Stock_Trend_Analysis_APP\stock-trend-ana-admin\venv\lib\site-packages\django\core\handlers\base.py", line 181, in _get_response
    response = wrapped_callback(request, *callback_args, **callback_kwargs)
  File "D:\Projects\Stock_Trend_Analysis_APP\stock-trend-ana-admin\sta_admin\analysis\views.py", line 35, in get_latest_news
    news = generate_score(raw_news, key="content")
  File "D:\Projects\Stock_Trend_Analysis_APP\stock-trend-ana-admin\sta_admin\common\SentimentalAnalyzer.py", line 18, in generate_score
    kv[scores] = scores
TypeError: unhashable type: 'dict'
[2021-03-13 05:24:23,612][Thread-1:6472][task_id:django.server][basehttp.py:157][ERROR]["GET /analysis/news/latest/AMZN HTTP/1.1" 500 83637]
[2021-03-23 00:37:03,625][Thread-4:17248][task_id:django.request][log.py:230][ERROR][Internal Server Error: /analysis/news/latest/TSLA2]
Traceback (most recent call last):
  File "D:\Projects\Stock_Trend_Analysis_APP\stock-trend-ana-admin\venv\lib\site-packages\django\core\handlers\exception.py", line 47, in inner
    response = get_response(request)
  File "D:\Projects\Stock_Trend_Analysis_APP\stock-trend-ana-admin\venv\lib\site-packages\django\core\handlers\base.py", line 181, in _get_response
    response = wrapped_callback(request, *callback_args, **callback_kwargs)
  File "D:\Projects\Stock_Trend_Analysis_APP\stock-trend-ana-admin\sta_admin\analysis\views.py", line 33, in get_latest_news
    raw_news = crawl_news(stock)
  File "D:\Projects\Stock_Trend_Analysis_APP\stock-trend-ana-admin\sta_admin\common\NewCollector.py", line 40, in crawl_news
    logger.warn("Something bad happened, when crawl news data. since the Http Code is " + response.status_code)
TypeError: must be str, not int
[2021-03-23 00:37:03,627][Thread-4:17248][task_id:django.server][basehttp.py:157][ERROR]["GET /analysis/news/latest/TSLA2 HTTP/1.1" 500 78966]
[2021-03-23 00:39:14,199][Thread-6:7724][task_id:django.request][log.py:230][ERROR][Internal Server Error: /analysis/news/latest/TSLA2]
Traceback (most recent call last):
  File "D:\Projects\Stock_Trend_Analysis_APP\stock-trend-ana-admin\venv\lib\site-packages\django\core\handlers\exception.py", line 47, in inner
    response = get_response(request)
  File "D:\Projects\Stock_Trend_Analysis_APP\stock-trend-ana-admin\venv\lib\site-packages\django\core\handlers\base.py", line 181, in _get_response
    response = wrapped_callback(request, *callback_args, **callback_kwargs)
  File "D:\Projects\Stock_Trend_Analysis_APP\stock-trend-ana-admin\sta_admin\analysis\views.py", line 33, in get_latest_news
    raw_news = crawl_news(stock)
  File "D:\Projects\Stock_Trend_Analysis_APP\stock-trend-ana-admin\sta_admin\common\NewCollector.py", line 40, in crawl_news
    logger.warn("Something bad happened, when crawl news data. since the Http Code is " + response.status_code)
TypeError: must be str, not int
[2021-03-23 00:39:14,206][Thread-6:7724][task_id:django.server][basehttp.py:157][ERROR]["GET /analysis/news/latest/TSLA2 HTTP/1.1" 500 82057]
[2021-03-23 19:44:30,574][Thread-1:12532][task_id:django.request][log.py:230][ERROR][Internal Server Error: /analysis/basic/2015-01-01/AMZN]
Traceback (most recent call last):
  File "D:\Projects\Stock_Trend_Analysis_APP\stock-trend-ana-admin\venv\lib\site-packages\django\core\handlers\exception.py", line 47, in inner
    response = get_response(request)
  File "D:\Projects\Stock_Trend_Analysis_APP\stock-trend-ana-admin\venv\lib\site-packages\django\core\handlers\base.py", line 181, in _get_response
    response = wrapped_callback(request, *callback_args, **callback_kwargs)
  File "D:\Projects\Stock_Trend_Analysis_APP\stock-trend-ana-admin\sta_admin\analysis\views.py", line 44, in get_basic_info
    return JsonResponseResult().ok(data=data_items)
  File "D:\Projects\Stock_Trend_Analysis_APP\stock-trend-ana-admin\sta_admin\common\JsonResponseResult.py", line 23, in ok
    self.__init__(data=data, code=code, msg=msg, **kwargs)
  File "D:\Projects\Stock_Trend_Analysis_APP\stock-trend-ana-admin\sta_admin\common\JsonResponseResult.py", line 14, in __init__
    super().__init__(content=json.dumps(self.data), **kwargs)
  File "C:\Users\AARON-PREDATOR\AppData\Local\Programs\Python\Python36\lib\json\__init__.py", line 231, in dumps
    return _default_encoder.encode(obj)
  File "C:\Users\AARON-PREDATOR\AppData\Local\Programs\Python\Python36\lib\json\encoder.py", line 199, in encode
    chunks = self.iterencode(o, _one_shot=True)
  File "C:\Users\AARON-PREDATOR\AppData\Local\Programs\Python\Python36\lib\json\encoder.py", line 257, in iterencode
    return _iterencode(o, 0)
  File "C:\Users\AARON-PREDATOR\AppData\Local\Programs\Python\Python36\lib\json\encoder.py", line 180, in default
    o.__class__.__name__)
TypeError: Object of type 'Timestamp' is not JSON serializable
[2021-03-23 19:44:30,579][Thread-1:12532][task_id:django.server][basehttp.py:157][ERROR]["GET /analysis/basic/2015-01-01/AMZN HTTP/1.1" 500 134916]
[2021-03-23 19:59:16,798][Thread-6:15224][task_id:django.request][log.py:230][ERROR][Internal Server Error: /analysis/basic/2015-01-01/AMZN]
Traceback (most recent call last):
  File "D:\Projects\Stock_Trend_Analysis_APP\stock-trend-ana-admin\venv\lib\site-packages\django\core\handlers\exception.py", line 47, in inner
    response = get_response(request)
  File "D:\Projects\Stock_Trend_Analysis_APP\stock-trend-ana-admin\venv\lib\site-packages\django\core\handlers\base.py", line 181, in _get_response
    response = wrapped_callback(request, *callback_args, **callback_kwargs)
  File "D:\Projects\Stock_Trend_Analysis_APP\stock-trend-ana-admin\sta_admin\analysis\views.py", line 44, in get_basic_info
    return JsonResponseResult().ok(data=data_items)
  File "D:\Projects\Stock_Trend_Analysis_APP\stock-trend-ana-admin\sta_admin\common\JsonResponseResult.py", line 23, in ok
    self.__init__(data=data, code=code, msg=msg, **kwargs)
  File "D:\Projects\Stock_Trend_Analysis_APP\stock-trend-ana-admin\sta_admin\common\JsonResponseResult.py", line 14, in __init__
    super().__init__(content=json.dumps(self.data), **kwargs)
  File "C:\Users\AARON-PREDATOR\AppData\Local\Programs\Python\Python36\lib\json\__init__.py", line 231, in dumps
    return _default_encoder.encode(obj)
  File "C:\Users\AARON-PREDATOR\AppData\Local\Programs\Python\Python36\lib\json\encoder.py", line 199, in encode
    chunks = self.iterencode(o, _one_shot=True)
  File "C:\Users\AARON-PREDATOR\AppData\Local\Programs\Python\Python36\lib\json\encoder.py", line 257, in iterencode
    return _iterencode(o, 0)
  File "C:\Users\AARON-PREDATOR\AppData\Local\Programs\Python\Python36\lib\json\encoder.py", line 180, in default
    o.__class__.__name__)
TypeError: Object of type 'Timestamp' is not JSON serializable
[2021-03-23 19:59:16,808][Thread-6:15224][task_id:django.server][basehttp.py:157][ERROR]["GET /analysis/basic/2015-01-01/AMZN HTTP/1.1" 500 137860]
[2021-03-23 20:44:17,304][Thread-6:19644][task_id:django.request][log.py:230][ERROR][Internal Server Error: /analysis/basic/2015-01-01/AMZN]
Traceback (most recent call last):
  File "D:\Projects\Stock_Trend_Analysis_APP\stock-trend-ana-admin\venv\lib\site-packages\django\core\handlers\exception.py", line 47, in inner
    response = get_response(request)
  File "D:\Projects\Stock_Trend_Analysis_APP\stock-trend-ana-admin\venv\lib\site-packages\django\core\handlers\base.py", line 181, in _get_response
    response = wrapped_callback(request, *callback_args, **callback_kwargs)
  File "D:\Projects\Stock_Trend_Analysis_APP\stock-trend-ana-admin\sta_admin\analysis\views.py", line 42, in get_basic_info
    data_items = generator.download_basic_info()
  File "D:\Projects\Stock_Trend_Analysis_APP\stock-trend-ana-admin\sta_admin\common\StockDataGenerator.py", line 40, in download_basic_info
    data = data[data['Date'] >= self._stock.get_start_date()].copy()
  File "D:\Projects\Stock_Trend_Analysis_APP\stock-trend-ana-admin\venv\lib\site-packages\pandas\core\ops\common.py", line 65, in new_method
    return method(self, other)
  File "D:\Projects\Stock_Trend_Analysis_APP\stock-trend-ana-admin\venv\lib\site-packages\pandas\core\ops\__init__.py", line 370, in wrapper
    res_values = comparison_op(lvalues, rvalues, op)
  File "D:\Projects\Stock_Trend_Analysis_APP\stock-trend-ana-admin\venv\lib\site-packages\pandas\core\ops\array_ops.py", line 244, in comparison_op
    res_values = comp_method_OBJECT_ARRAY(op, lvalues, rvalues)
  File "D:\Projects\Stock_Trend_Analysis_APP\stock-trend-ana-admin\venv\lib\site-packages\pandas\core\ops\array_ops.py", line 56, in comp_method_OBJECT_ARRAY
    result = libops.scalar_compare(x.ravel(), y, op)
  File "pandas\_libs\ops.pyx", line 103, in pandas._libs.ops.scalar_compare
TypeError: '>=' not supported between instances of 'str' and 'datetime.datetime'
[2021-03-23 20:44:17,313][Thread-6:19644][task_id:django.server][basehttp.py:157][ERROR]["GET /analysis/basic/2015-01-01/AMZN HTTP/1.1" 500 108015]
[2021-03-23 20:53:51,349][Thread-6:3304][task_id:django.request][log.py:230][ERROR][Internal Server Error: /analysis/basic/2014-01-01/AMZN]
Traceback (most recent call last):
  File "D:\Projects\Stock_Trend_Analysis_APP\stock-trend-ana-admin\venv\lib\site-packages\pandas\core\indexes\base.py", line 2898, in get_loc
    return self._engine.get_loc(casted_key)
  File "pandas\_libs\index.pyx", line 70, in pandas._libs.index.IndexEngine.get_loc
  File "pandas\_libs\index.pyx", line 101, in pandas._libs.index.IndexEngine.get_loc
  File "pandas\_libs\hashtable_class_helper.pxi", line 1675, in pandas._libs.hashtable.PyObjectHashTable.get_item
  File "pandas\_libs\hashtable_class_helper.pxi", line 1683, in pandas._libs.hashtable.PyObjectHashTable.get_item
KeyError: 'Date'

The above exception was the direct cause of the following exception:

Traceback (most recent call last):
  File "D:\Projects\Stock_Trend_Analysis_APP\stock-trend-ana-admin\venv\lib\site-packages\django\core\handlers\exception.py", line 47, in inner
    response = get_response(request)
  File "D:\Projects\Stock_Trend_Analysis_APP\stock-trend-ana-admin\venv\lib\site-packages\django\core\handlers\base.py", line 181, in _get_response
    response = wrapped_callback(request, *callback_args, **callback_kwargs)
  File "D:\Projects\Stock_Trend_Analysis_APP\stock-trend-ana-admin\sta_admin\analysis\views.py", line 42, in get_basic_info
    data_items = generator.download_basic_info()
  File "D:\Projects\Stock_Trend_Analysis_APP\stock-trend-ana-admin\sta_admin\common\StockDataGenerator.py", line 48, in download_basic_info
    data = data[data['Date'] >= self._stock.get_start_date().strftime("%Y%m%d")].copy()
  File "D:\Projects\Stock_Trend_Analysis_APP\stock-trend-ana-admin\venv\lib\site-packages\pandas\core\frame.py", line 2906, in __getitem__
    indexer = self.columns.get_loc(key)
  File "D:\Projects\Stock_Trend_Analysis_APP\stock-trend-ana-admin\venv\lib\site-packages\pandas\core\indexes\base.py", line 2900, in get_loc
    raise KeyError(key) from err
KeyError: 'Date'
[2021-03-23 20:53:57,626][Thread-6:3304][task_id:django.server][basehttp.py:157][ERROR]["GET /analysis/basic/2014-01-01/AMZN HTTP/1.1" 500 148891]
[2021-03-23 21:02:08,630][Thread-6:19356][task_id:django.request][log.py:230][ERROR][Internal Server Error: /analysis/basic/2014-01-01/AMZN]
Traceback (most recent call last):
  File "D:\Projects\Stock_Trend_Analysis_APP\stock-trend-ana-admin\venv\lib\site-packages\pandas\core\indexes\base.py", line 2898, in get_loc
    return self._engine.get_loc(casted_key)
  File "pandas\_libs\index.pyx", line 70, in pandas._libs.index.IndexEngine.get_loc
  File "pandas\_libs\index.pyx", line 101, in pandas._libs.index.IndexEngine.get_loc
  File "pandas\_libs\hashtable_class_helper.pxi", line 1675, in pandas._libs.hashtable.PyObjectHashTable.get_item
  File "pandas\_libs\hashtable_class_helper.pxi", line 1683, in pandas._libs.hashtable.PyObjectHashTable.get_item
KeyError: 'Date'

The above exception was the direct cause of the following exception:

Traceback (most recent call last):
  File "D:\Projects\Stock_Trend_Analysis_APP\stock-trend-ana-admin\venv\lib\site-packages\django\core\handlers\exception.py", line 47, in inner
    response = get_response(request)
  File "D:\Projects\Stock_Trend_Analysis_APP\stock-trend-ana-admin\venv\lib\site-packages\django\core\handlers\base.py", line 181, in _get_response
    response = wrapped_callback(request, *callback_args, **callback_kwargs)
  File "D:\Projects\Stock_Trend_Analysis_APP\stock-trend-ana-admin\sta_admin\analysis\views.py", line 42, in get_basic_info
    data_items = generator.download_basic_info()
  File "D:\Projects\Stock_Trend_Analysis_APP\stock-trend-ana-admin\sta_admin\common\StockDataGenerator.py", line 48, in download_basic_info
    ss = len(data['Date'])
  File "D:\Projects\Stock_Trend_Analysis_APP\stock-trend-ana-admin\venv\lib\site-packages\pandas\core\frame.py", line 2906, in __getitem__
    indexer = self.columns.get_loc(key)
  File "D:\Projects\Stock_Trend_Analysis_APP\stock-trend-ana-admin\venv\lib\site-packages\pandas\core\indexes\base.py", line 2900, in get_loc
    raise KeyError(key) from err
KeyError: 'Date'
[2021-03-23 21:02:23,977][Thread-6:19356][task_id:django.server][basehttp.py:157][ERROR]["GET /analysis/basic/2014-01-01/AMZN HTTP/1.1" 500 148841]
[2021-03-24 01:22:17,072][Thread-1:7924][task_id:django.request][log.py:230][ERROR][Internal Server Error: /analysis/predict/2015-01-01/AMZN]
Traceback (most recent call last):
  File "D:\Projects\Stock_Trend_Analysis_APP\stock-trend-ana-admin\venv\lib\site-packages\pandas\core\indexes\base.py", line 2898, in get_loc
    return self._engine.get_loc(casted_key)
  File "pandas\_libs\index.pyx", line 70, in pandas._libs.index.IndexEngine.get_loc
  File "pandas\_libs\index.pyx", line 101, in pandas._libs.index.IndexEngine.get_loc
  File "pandas\_libs\hashtable_class_helper.pxi", line 1675, in pandas._libs.hashtable.PyObjectHashTable.get_item
  File "pandas\_libs\hashtable_class_helper.pxi", line 1683, in pandas._libs.hashtable.PyObjectHashTable.get_item
KeyError: 'Date'

The above exception was the direct cause of the following exception:

Traceback (most recent call last):
  File "D:\Projects\Stock_Trend_Analysis_APP\stock-trend-ana-admin\venv\lib\site-packages\django\core\handlers\exception.py", line 47, in inner
    response = get_response(request)
  File "D:\Projects\Stock_Trend_Analysis_APP\stock-trend-ana-admin\venv\lib\site-packages\django\core\handlers\base.py", line 181, in _get_response
    response = wrapped_callback(request, *callback_args, **callback_kwargs)
  File "D:\Projects\Stock_Trend_Analysis_APP\stock-trend-ana-admin\sta_admin\analysis\views.py", line 55, in predict_future_price
    x_test, y_test, test_dataset = generator.generate_future_data()
  File "D:\Projects\Stock_Trend_Analysis_APP\stock-trend-ana-admin\sta_admin\common\StockDataGenerator.py", line 118, in generate_future_data
    training_data = data[data['Date'] < self._stock.get_validation_date()].copy()
  File "D:\Projects\Stock_Trend_Analysis_APP\stock-trend-ana-admin\venv\lib\site-packages\pandas\core\frame.py", line 2906, in __getitem__
    indexer = self.columns.get_loc(key)
  File "D:\Projects\Stock_Trend_Analysis_APP\stock-trend-ana-admin\venv\lib\site-packages\pandas\core\indexes\base.py", line 2900, in get_loc
    raise KeyError(key) from err
KeyError: 'Date'
[2021-03-24 01:22:17,079][Thread-1:7924][task_id:django.server][basehttp.py:157][ERROR]["GET /analysis/predict/2015-01-01/AMZN HTTP/1.1" 500 150249]
[2021-03-24 01:23:43,089][Thread-1:1912][task_id:django.request][log.py:230][ERROR][Internal Server Error: /analysis/predict/2015-01-01/AMZN]
Traceback (most recent call last):
  File "D:\Projects\Stock_Trend_Analysis_APP\stock-trend-ana-admin\venv\lib\site-packages\django\core\handlers\exception.py", line 47, in inner
    response = get_response(request)
  File "D:\Projects\Stock_Trend_Analysis_APP\stock-trend-ana-admin\venv\lib\site-packages\django\core\handlers\base.py", line 181, in _get_response
    response = wrapped_callback(request, *callback_args, **callback_kwargs)
  File "D:\Projects\Stock_Trend_Analysis_APP\stock-trend-ana-admin\sta_admin\analysis\views.py", line 55, in predict_future_price
    x_test, y_test, test_dataset = generator.generate_future_data()
  File "D:\Projects\Stock_Trend_Analysis_APP\stock-trend-ana-admin\sta_admin\common\StockDataGenerator.py", line 127, in generate_future_data
    tomorrow_date = latest_date + timedelta(1)
TypeError: must be str, not datetime.timedelta
[2021-03-24 01:23:43,091][Thread-1:1912][task_id:django.server][basehttp.py:157][ERROR]["GET /analysis/predict/2015-01-01/AMZN HTTP/1.1" 500 90305]
[2021-03-24 01:45:27,365][Thread-6:8784][task_id:django.request][log.py:230][ERROR][Internal Server Error: /analysis/predict/2015-01-01/AMZN]
Traceback (most recent call last):
  File "D:\Projects\Stock_Trend_Analysis_APP\stock-trend-ana-admin\venv\lib\site-packages\django\core\handlers\exception.py", line 47, in inner
    response = get_response(request)
  File "D:\Projects\Stock_Trend_Analysis_APP\stock-trend-ana-admin\venv\lib\site-packages\django\core\handlers\base.py", line 181, in _get_response
    response = wrapped_callback(request, *callback_args, **callback_kwargs)
  File "D:\Projects\Stock_Trend_Analysis_APP\stock-trend-ana-admin\sta_admin\analysis\views.py", line 55, in predict_future_price
    x_test, y_test, test_dataset = generator.generate_future_data()
  File "D:\Projects\Stock_Trend_Analysis_APP\stock-trend-ana-admin\sta_admin\common\StockDataGenerator.py", line 87, in generate_future_data
    latest_date = datetime.timestamp(test_data[-1:]['Close'].idxmin())
TypeError: descriptor 'timestamp' requires a 'datetime.datetime' object but received a 'str'
[2021-03-24 01:45:27,375][Thread-6:8784][task_id:django.server][basehttp.py:157][ERROR]["GET /analysis/predict/2015-01-01/AMZN HTTP/1.1" 500 93451]
[2021-03-24 01:46:36,972][Thread-6:8088][task_id:django.request][log.py:230][ERROR][Internal Server Error: /analysis/predict/2015-01-01/AMZN]
Traceback (most recent call last):
  File "D:\Projects\Stock_Trend_Analysis_APP\stock-trend-ana-admin\venv\lib\site-packages\django\core\handlers\exception.py", line 47, in inner
    response = get_response(request)
  File "D:\Projects\Stock_Trend_Analysis_APP\stock-trend-ana-admin\venv\lib\site-packages\django\core\handlers\base.py", line 181, in _get_response
    response = wrapped_callback(request, *callback_args, **callback_kwargs)
  File "D:\Projects\Stock_Trend_Analysis_APP\stock-trend-ana-admin\sta_admin\analysis\views.py", line 55, in predict_future_price
    x_test, y_test, test_dataset = generator.generate_future_data()
  File "D:\Projects\Stock_Trend_Analysis_APP\stock-trend-ana-admin\sta_admin\common\StockDataGenerator.py", line 89, in generate_future_data
    tomorrow_date = latest_date + timedelta(1)
TypeError: unsupported operand type(s) for +: 'float' and 'datetime.timedelta'
[2021-03-24 01:46:36,977][Thread-6:8088][task_id:django.server][basehttp.py:157][ERROR]["GET /analysis/predict/2015-01-01/AMZN HTTP/1.1" 500 93687]
[2021-03-24 01:53:33,375][Thread-6:17572][task_id:django.request][log.py:230][ERROR][Internal Server Error: /analysis/predict/2015-01-01/AMZN]
Traceback (most recent call last):
  File "D:\Projects\Stock_Trend_Analysis_APP\stock-trend-ana-admin\venv\lib\site-packages\django\core\handlers\exception.py", line 47, in inner
    response = get_response(request)
  File "D:\Projects\Stock_Trend_Analysis_APP\stock-trend-ana-admin\venv\lib\site-packages\django\core\handlers\base.py", line 181, in _get_response
    response = wrapped_callback(request, *callback_args, **callback_kwargs)
  File "D:\Projects\Stock_Trend_Analysis_APP\stock-trend-ana-admin\sta_admin\analysis\views.py", line 55, in predict_future_price
    x_test, y_test, test_dataset = generator.generate_future_data()
  File "D:\Projects\Stock_Trend_Analysis_APP\stock-trend-ana-admin\sta_admin\common\StockDataGenerator.py", line 116, in generate_future_data
    test_scaled = min_max.fit_transform(test_data)
AttributeError: 'numpy.ndarray' object has no attribute 'fit_transform'
[2021-03-24 01:53:33,382][Thread-6:17572][task_id:django.server][basehttp.py:157][ERROR]["GET /analysis/predict/2015-01-01/AMZN HTTP/1.1" 500 102697]
[2021-03-24 02:02:41,453][Thread-6:2424][task_id:django.request][log.py:230][ERROR][Internal Server Error: /analysis/predict/2015-01-01/AMZN]
Traceback (most recent call last):
  File "D:\Projects\Stock_Trend_Analysis_APP\stock-trend-ana-admin\venv\lib\site-packages\django\core\handlers\exception.py", line 47, in inner
    response = get_response(request)
  File "D:\Projects\Stock_Trend_Analysis_APP\stock-trend-ana-admin\venv\lib\site-packages\django\core\handlers\base.py", line 181, in _get_response
    response = wrapped_callback(request, *callback_args, **callback_kwargs)
  File "D:\Projects\Stock_Trend_Analysis_APP\stock-trend-ana-admin\sta_admin\analysis\views.py", line 58, in predict_future_price
    return JsonResponseResult().ok(data=x_test)
  File "D:\Projects\Stock_Trend_Analysis_APP\stock-trend-ana-admin\sta_admin\common\JsonResponseResult.py", line 23, in ok
    self.__init__(data=data, code=code, msg=msg, **kwargs)
  File "D:\Projects\Stock_Trend_Analysis_APP\stock-trend-ana-admin\sta_admin\common\JsonResponseResult.py", line 10, in __init__
    if not data: data = list()
ValueError: The truth value of an array with more than one element is ambiguous. Use a.any() or a.all()
[2021-03-24 02:02:41,457][Thread-6:2424][task_id:django.server][basehttp.py:157][ERROR]["GET /analysis/predict/2015-01-01/AMZN HTTP/1.1" 500 95562]
[2021-03-24 03:27:06,613][Thread-6:10420][task_id:django.request][log.py:230][ERROR][Internal Server Error: /analysis/predict/2015-01-01/AMZN]
Traceback (most recent call last):
  File "D:\Projects\Stock_Trend_Analysis_APP\stock-trend-ana-admin\venv\lib\site-packages\django\core\handlers\exception.py", line 47, in inner
    response = get_response(request)
  File "D:\Projects\Stock_Trend_Analysis_APP\stock-trend-ana-admin\venv\lib\site-packages\django\core\handlers\base.py", line 181, in _get_response
    response = wrapped_callback(request, *callback_args, **callback_kwargs)
  File "D:\Projects\Stock_Trend_Analysis_APP\stock-trend-ana-admin\sta_admin\analysis\views.py", line 63, in predict_future_price
    y_test = model.predict(generator)
  File "D:\Projects\Stock_Trend_Analysis_APP\stock-trend-ana-admin\sta_admin\common\ModelLoader.py", line 36, in predict
    y_test = dataGenerator.get_min_max().inverse_transform(y_test)
  File "D:\Projects\Stock_Trend_Analysis_APP\stock-trend-ana-admin\venv\lib\site-packages\sklearn\preprocessing\_data.py", line 461, in inverse_transform
    X -= self.min_
ValueError: non-broadcastable output operand with shape (296,1) doesn't match the broadcast shape (296,2)
[2021-03-24 03:27:06,618][Thread-6:10420][task_id:django.server][basehttp.py:157][ERROR]["GET /analysis/predict/2015-01-01/AMZN HTTP/1.1" 500 102469]
[2021-03-24 03:28:51,521][Thread-6:12184][task_id:django.request][log.py:230][ERROR][Internal Server Error: /analysis/predict/2015-01-01/AMZN]
Traceback (most recent call last):
  File "D:\Projects\Stock_Trend_Analysis_APP\stock-trend-ana-admin\venv\lib\site-packages\django\core\handlers\exception.py", line 47, in inner
    response = get_response(request)
  File "D:\Projects\Stock_Trend_Analysis_APP\stock-trend-ana-admin\venv\lib\site-packages\django\core\handlers\base.py", line 181, in _get_response
    response = wrapped_callback(request, *callback_args, **callback_kwargs)
  File "D:\Projects\Stock_Trend_Analysis_APP\stock-trend-ana-admin\sta_admin\analysis\views.py", line 63, in predict_future_price
    y_test = model.predict(generator)
  File "D:\Projects\Stock_Trend_Analysis_APP\stock-trend-ana-admin\sta_admin\common\ModelLoader.py", line 40, in predict
    latest_date = datetime.strptime(test_dataset[-1:]['Close'].idxmin(), '%Y-%m-%d')
TypeError: strptime() argument 1 must be str, not Timestamp
[2021-03-24 03:28:51,524][Thread-6:12184][task_id:django.server][basehttp.py:157][ERROR]["GET /analysis/predict/2015-01-01/AMZN HTTP/1.1" 500 94417]
[2021-03-24 03:30:35,741][Thread-6:19040][task_id:django.request][log.py:230][ERROR][Internal Server Error: /analysis/predict/2015-01-01/AMZN]
Traceback (most recent call last):
  File "D:\Projects\Stock_Trend_Analysis_APP\stock-trend-ana-admin\venv\lib\site-packages\django\core\handlers\exception.py", line 47, in inner
    response = get_response(request)
  File "D:\Projects\Stock_Trend_Analysis_APP\stock-trend-ana-admin\venv\lib\site-packages\django\core\handlers\base.py", line 181, in _get_response
    response = wrapped_callback(request, *callback_args, **callback_kwargs)
  File "D:\Projects\Stock_Trend_Analysis_APP\stock-trend-ana-admin\sta_admin\analysis\views.py", line 63, in predict_future_price
    y_test = model.predict(generator)
  File "D:\Projects\Stock_Trend_Analysis_APP\stock-trend-ana-admin\sta_admin\common\ModelLoader.py", line 45, in predict
    y_test = np.concatenate([date_arr, y_test], axis=1)
  File "<__array_function__ internals>", line 6, in concatenate
numpy.AxisError: axis 1 is out of bounds for array of dimension 1
[2021-03-24 03:30:35,746][Thread-6:19040][task_id:django.server][basehttp.py:157][ERROR]["GET /analysis/predict/2015-01-01/AMZN HTTP/1.1" 500 111525]
[2021-03-24 03:40:59,600][Thread-6:1048][task_id:django.request][log.py:230][ERROR][Internal Server Error: /analysis/predict/2015-01-01/AMZN]
Traceback (most recent call last):
  File "D:\Projects\Stock_Trend_Analysis_APP\stock-trend-ana-admin\venv\lib\site-packages\django\core\handlers\exception.py", line 47, in inner
    response = get_response(request)
  File "D:\Projects\Stock_Trend_Analysis_APP\stock-trend-ana-admin\venv\lib\site-packages\django\core\handlers\base.py", line 181, in _get_response
    response = wrapped_callback(request, *callback_args, **callback_kwargs)
  File "D:\Projects\Stock_Trend_Analysis_APP\stock-trend-ana-admin\sta_admin\analysis\views.py", line 63, in predict_future_price
    y_test = model.predict(generator)
  File "D:\Projects\Stock_Trend_Analysis_APP\stock-trend-ana-admin\sta_admin\common\ModelLoader.py", line 41, in predict
    y_test = np.concatenate([date_arr, y_test], axis=1)
  File "<__array_function__ internals>", line 6, in concatenate
numpy.AxisError: axis 1 is out of bounds for array of dimension 1
[2021-03-24 03:40:59,606][Thread-6:1048][task_id:django.server][basehttp.py:157][ERROR]["GET /analysis/predict/2015-01-01/AMZN HTTP/1.1" 500 115419]
[2021-03-24 03:44:24,125][Thread-6:11052][task_id:django.request][log.py:230][ERROR][Internal Server Error: /analysis/predict/2015-01-01/AMZN]
Traceback (most recent call last):
  File "D:\Projects\Stock_Trend_Analysis_APP\stock-trend-ana-admin\venv\lib\site-packages\django\core\handlers\exception.py", line 47, in inner
    response = get_response(request)
  File "D:\Projects\Stock_Trend_Analysis_APP\stock-trend-ana-admin\venv\lib\site-packages\django\core\handlers\base.py", line 181, in _get_response
    response = wrapped_callback(request, *callback_args, **callback_kwargs)
  File "D:\Projects\Stock_Trend_Analysis_APP\stock-trend-ana-admin\sta_admin\analysis\views.py", line 63, in predict_future_price
    y_test = model.predict(generator)
  File "D:\Projects\Stock_Trend_Analysis_APP\stock-trend-ana-admin\sta_admin\common\ModelLoader.py", line 41, in predict
    for timestamp_obj in test_dataset.index.tolist()][:len(y_test)])
  File "<__array_function__ internals>", line 6, in concatenate
numpy.AxisError: axis 1 is out of bounds for array of dimension 1
[2021-03-24 03:44:24,131][Thread-6:11052][task_id:django.server][basehttp.py:157][ERROR]["GET /analysis/predict/2015-01-01/AMZN HTTP/1.1" 500 115574]
[2021-03-24 03:52:32,125][Thread-6:4184][task_id:django.request][log.py:230][ERROR][Internal Server Error: /analysis/predict/2015-01-01/AMZN]
Traceback (most recent call last):
  File "D:\Projects\Stock_Trend_Analysis_APP\stock-trend-ana-admin\venv\lib\site-packages\django\core\handlers\exception.py", line 47, in inner
    response = get_response(request)
  File "D:\Projects\Stock_Trend_Analysis_APP\stock-trend-ana-admin\venv\lib\site-packages\django\core\handlers\base.py", line 181, in _get_response
    response = wrapped_callback(request, *callback_args, **callback_kwargs)
  File "D:\Projects\Stock_Trend_Analysis_APP\stock-trend-ana-admin\sta_admin\analysis\views.py", line 65, in predict_future_price
    return JsonResponseResult().ok(data=y_test)
  File "D:\Projects\Stock_Trend_Analysis_APP\stock-trend-ana-admin\sta_admin\common\JsonResponseResult.py", line 23, in ok
    self.__init__(data=data, code=code, msg=msg, **kwargs)
  File "D:\Projects\Stock_Trend_Analysis_APP\stock-trend-ana-admin\sta_admin\common\JsonResponseResult.py", line 10, in __init__
    if not data: data = list()
ValueError: The truth value of an array with more than one element is ambiguous. Use a.any() or a.all()
[2021-03-24 03:52:32,130][Thread-6:4184][task_id:django.server][basehttp.py:157][ERROR]["GET /analysis/predict/2015-01-01/AMZN HTTP/1.1" 500 108340]
[2021-03-24 03:54:43,634][Thread-6:2424][task_id:django.request][log.py:230][ERROR][Internal Server Error: /analysis/predict/2013-01-01/AMZN]
Traceback (most recent call last):
  File "D:\Projects\Stock_Trend_Analysis_APP\stock-trend-ana-admin\venv\lib\site-packages\pandas\core\indexes\base.py", line 2898, in get_loc
    return self._engine.get_loc(casted_key)
  File "pandas\_libs\index.pyx", line 70, in pandas._libs.index.IndexEngine.get_loc
  File "pandas\_libs\index.pyx", line 101, in pandas._libs.index.IndexEngine.get_loc
  File "pandas\_libs\hashtable_class_helper.pxi", line 1675, in pandas._libs.hashtable.PyObjectHashTable.get_item
  File "pandas\_libs\hashtable_class_helper.pxi", line 1683, in pandas._libs.hashtable.PyObjectHashTable.get_item
KeyError: 'Date'

The above exception was the direct cause of the following exception:

Traceback (most recent call last):
  File "D:\Projects\Stock_Trend_Analysis_APP\stock-trend-ana-admin\venv\lib\site-packages\django\core\handlers\exception.py", line 47, in inner
    response = get_response(request)
  File "D:\Projects\Stock_Trend_Analysis_APP\stock-trend-ana-admin\venv\lib\site-packages\django\core\handlers\base.py", line 181, in _get_response
    response = wrapped_callback(request, *callback_args, **callback_kwargs)
  File "D:\Projects\Stock_Trend_Analysis_APP\stock-trend-ana-admin\sta_admin\analysis\views.py", line 63, in predict_future_price
    y_test = model.predict(generator)
  File "D:\Projects\Stock_Trend_Analysis_APP\stock-trend-ana-admin\sta_admin\common\ModelLoader.py", line 34, in predict
    x_test, _, test_dataset = dataGenerator.generate_future_data()
  File "D:\Projects\Stock_Trend_Analysis_APP\stock-trend-ana-admin\sta_admin\common\StockDataGenerator.py", line 86, in generate_future_data
    training_data = data[data['Date'] < self._stock.get_validation_date()].copy()
  File "D:\Projects\Stock_Trend_Analysis_APP\stock-trend-ana-admin\venv\lib\site-packages\pandas\core\frame.py", line 2906, in __getitem__
    indexer = self.columns.get_loc(key)
  File "D:\Projects\Stock_Trend_Analysis_APP\stock-trend-ana-admin\venv\lib\site-packages\pandas\core\indexes\base.py", line 2900, in get_loc
    raise KeyError(key) from err
KeyError: 'Date'
[2021-03-24 03:54:43,646][Thread-6:2424][task_id:django.server][basehttp.py:157][ERROR]["GET /analysis/predict/2013-01-01/AMZN HTTP/1.1" 500 157330]
[2021-03-24 04:03:31,908][Thread-1:16408][task_id:django.request][log.py:230][ERROR][Internal Server Error: /analysis/predict/2012-01-01/AMZN]
Traceback (most recent call last):
  File "D:\Projects\Stock_Trend_Analysis_APP\stock-trend-ana-admin\venv\lib\site-packages\pandas\core\indexes\base.py", line 2898, in get_loc
    return self._engine.get_loc(casted_key)
  File "pandas\_libs\index.pyx", line 70, in pandas._libs.index.IndexEngine.get_loc
  File "pandas\_libs\index.pyx", line 101, in pandas._libs.index.IndexEngine.get_loc
  File "pandas\_libs\hashtable_class_helper.pxi", line 1675, in pandas._libs.hashtable.PyObjectHashTable.get_item
  File "pandas\_libs\hashtable_class_helper.pxi", line 1683, in pandas._libs.hashtable.PyObjectHashTable.get_item
KeyError: 'Date'

The above exception was the direct cause of the following exception:

Traceback (most recent call last):
  File "D:\Projects\Stock_Trend_Analysis_APP\stock-trend-ana-admin\venv\lib\site-packages\django\core\handlers\exception.py", line 47, in inner
    response = get_response(request)
  File "D:\Projects\Stock_Trend_Analysis_APP\stock-trend-ana-admin\venv\lib\site-packages\django\core\handlers\base.py", line 181, in _get_response
    response = wrapped_callback(request, *callback_args, **callback_kwargs)
  File "D:\Projects\Stock_Trend_Analysis_APP\stock-trend-ana-admin\sta_admin\analysis\views.py", line 63, in predict_future_price
    y_test = model.predict(generator)
  File "D:\Projects\Stock_Trend_Analysis_APP\stock-trend-ana-admin\sta_admin\common\ModelLoader.py", line 34, in predict
    x_test, _, test_dataset = dataGenerator.generate_future_data()
  File "D:\Projects\Stock_Trend_Analysis_APP\stock-trend-ana-admin\sta_admin\common\StockDataGenerator.py", line 87, in generate_future_data
    training_data = data[data['Date'] < self._stock.get_validation_date()].copy()
  File "D:\Projects\Stock_Trend_Analysis_APP\stock-trend-ana-admin\venv\lib\site-packages\pandas\core\frame.py", line 2906, in __getitem__
    indexer = self.columns.get_loc(key)
  File "D:\Projects\Stock_Trend_Analysis_APP\stock-trend-ana-admin\venv\lib\site-packages\pandas\core\indexes\base.py", line 2900, in get_loc
    raise KeyError(key) from err
KeyError: 'Date'
[2021-03-24 04:03:31,914][Thread-1:16408][task_id:django.server][basehttp.py:157][ERROR]["GET /analysis/predict/2012-01-01/AMZN HTTP/1.1" 500 154376]
[2021-03-24 04:05:37,412][Thread-6:6712][task_id:django.request][log.py:230][ERROR][Internal Server Error: /analysis/predict/2011-01-01/AMZN]
Traceback (most recent call last):
  File "D:\Projects\Stock_Trend_Analysis_APP\stock-trend-ana-admin\venv\lib\site-packages\pandas\core\indexes\base.py", line 2898, in get_loc
    return self._engine.get_loc(casted_key)
  File "pandas\_libs\index.pyx", line 70, in pandas._libs.index.IndexEngine.get_loc
  File "pandas\_libs\index.pyx", line 101, in pandas._libs.index.IndexEngine.get_loc
  File "pandas\_libs\hashtable_class_helper.pxi", line 1675, in pandas._libs.hashtable.PyObjectHashTable.get_item
  File "pandas\_libs\hashtable_class_helper.pxi", line 1683, in pandas._libs.hashtable.PyObjectHashTable.get_item
KeyError: 'Date'

The above exception was the direct cause of the following exception:

Traceback (most recent call last):
  File "D:\Projects\Stock_Trend_Analysis_APP\stock-trend-ana-admin\venv\lib\site-packages\django\core\handlers\exception.py", line 47, in inner
    response = get_response(request)
  File "D:\Projects\Stock_Trend_Analysis_APP\stock-trend-ana-admin\venv\lib\site-packages\django\core\handlers\base.py", line 181, in _get_response
    response = wrapped_callback(request, *callback_args, **callback_kwargs)
  File "D:\Projects\Stock_Trend_Analysis_APP\stock-trend-ana-admin\sta_admin\analysis\views.py", line 63, in predict_future_price
    y_test = model.predict(generator)
  File "D:\Projects\Stock_Trend_Analysis_APP\stock-trend-ana-admin\sta_admin\common\ModelLoader.py", line 34, in predict
    x_test, _, test_dataset = dataGenerator.generate_future_data()
  File "D:\Projects\Stock_Trend_Analysis_APP\stock-trend-ana-admin\sta_admin\common\StockDataGenerator.py", line 87, in generate_future_data
    training_data = data[data['Date'] < self._stock.get_validation_date()].copy()
  File "D:\Projects\Stock_Trend_Analysis_APP\stock-trend-ana-admin\venv\lib\site-packages\pandas\core\frame.py", line 2906, in __getitem__
    indexer = self.columns.get_loc(key)
  File "D:\Projects\Stock_Trend_Analysis_APP\stock-trend-ana-admin\venv\lib\site-packages\pandas\core\indexes\base.py", line 2900, in get_loc
    raise KeyError(key) from err
KeyError: 'Date'
[2021-03-24 04:05:37,423][Thread-6:6712][task_id:django.server][basehttp.py:157][ERROR]["GET /analysis/predict/2011-01-01/AMZN HTTP/1.1" 500 157330]
[2021-03-24 04:13:24,458][Thread-6:11976][task_id:django.request][log.py:230][ERROR][Internal Server Error: /analysis/predict/2010-01-01/AMZN]
Traceback (most recent call last):
  File "D:\Projects\Stock_Trend_Analysis_APP\stock-trend-ana-admin\venv\lib\site-packages\django\core\handlers\exception.py", line 47, in inner
    response = get_response(request)
  File "D:\Projects\Stock_Trend_Analysis_APP\stock-trend-ana-admin\venv\lib\site-packages\django\core\handlers\base.py", line 181, in _get_response
    response = wrapped_callback(request, *callback_args, **callback_kwargs)
  File "D:\Projects\Stock_Trend_Analysis_APP\stock-trend-ana-admin\sta_admin\analysis\views.py", line 63, in predict_future_price
    y_test = model.predict(generator)
  File "D:\Projects\Stock_Trend_Analysis_APP\stock-trend-ana-admin\sta_admin\common\ModelLoader.py", line 34, in predict
    x_test, _, test_dataset = dataGenerator.generate_future_data()
  File "D:\Projects\Stock_Trend_Analysis_APP\stock-trend-ana-admin\sta_admin\common\StockDataGenerator.py", line 95, in generate_future_data
    latest_date = datetime.strptime(test_data[-1:]['Close'].idxmin(), '%Y-%m-%d')
TypeError: strptime() argument 1 must be str, not Timestamp
[2021-03-24 04:13:24,463][Thread-6:11976][task_id:django.server][basehttp.py:157][ERROR]["GET /analysis/predict/2010-01-01/AMZN HTTP/1.1" 500 96770]
[2021-03-24 04:14:26,882][Thread-6:11976][task_id:django.request][log.py:230][ERROR][Internal Server Error: /analysis/predict/2009-01-01/AMZN]
Traceback (most recent call last):
  File "D:\Projects\Stock_Trend_Analysis_APP\stock-trend-ana-admin\venv\lib\site-packages\django\core\handlers\exception.py", line 47, in inner
    response = get_response(request)
  File "D:\Projects\Stock_Trend_Analysis_APP\stock-trend-ana-admin\venv\lib\site-packages\django\core\handlers\base.py", line 181, in _get_response
    response = wrapped_callback(request, *callback_args, **callback_kwargs)
  File "D:\Projects\Stock_Trend_Analysis_APP\stock-trend-ana-admin\sta_admin\analysis\views.py", line 63, in predict_future_price
    y_test = model.predict(generator)
  File "D:\Projects\Stock_Trend_Analysis_APP\stock-trend-ana-admin\sta_admin\common\ModelLoader.py", line 34, in predict
    x_test, _, test_dataset = dataGenerator.generate_future_data()
  File "D:\Projects\Stock_Trend_Analysis_APP\stock-trend-ana-admin\sta_admin\common\StockDataGenerator.py", line 95, in generate_future_data
    latest_date = datetime.strptime(test_data[-1:]['Close'].idxmin(), '%Y-%m-%d')
TypeError: strptime() argument 1 must be str, not Timestamp
[2021-03-24 04:14:26,885][Thread-6:11976][task_id:django.server][basehttp.py:157][ERROR]["GET /analysis/predict/2009-01-01/AMZN HTTP/1.1" 500 96633]
[2021-03-27 18:34:16,806][Thread-3:7088][task_id:django.request][log.py:230][ERROR][Internal Server Error: /analysis/basic/2015-01-01/AMZN]
Traceback (most recent call last):
  File "D:\Projects\Stock_Trend_Analysis_APP\stock-trend-ana-admin\venv\lib\site-packages\django\core\handlers\exception.py", line 47, in inner
    response = get_response(request)
  File "D:\Projects\Stock_Trend_Analysis_APP\stock-trend-ana-admin\venv\lib\site-packages\django\core\handlers\base.py", line 181, in _get_response
    response = wrapped_callback(request, *callback_args, **callback_kwargs)
  File "D:\Projects\Stock_Trend_Analysis_APP\stock-trend-ana-admin\sta_admin\analysis\views.py", line 45, in get_basic_info
    return JsonResponseResult().ok(data=data_items)
  File "D:\Projects\Stock_Trend_Analysis_APP\stock-trend-ana-admin\sta_admin\common\JsonResponseResult.py", line 23, in ok
    self.__init__(data=data, code=code, msg=msg, **kwargs)
  File "D:\Projects\Stock_Trend_Analysis_APP\stock-trend-ana-admin\sta_admin\common\JsonResponseResult.py", line 14, in __init__
    super().__init__(content=json.dumps(self.data), **kwargs)
  File "C:\Users\AARON-PREDATOR\AppData\Local\Programs\Python\Python36\lib\json\__init__.py", line 231, in dumps
    return _default_encoder.encode(obj)
  File "C:\Users\AARON-PREDATOR\AppData\Local\Programs\Python\Python36\lib\json\encoder.py", line 199, in encode
    chunks = self.iterencode(o, _one_shot=True)
  File "C:\Users\AARON-PREDATOR\AppData\Local\Programs\Python\Python36\lib\json\encoder.py", line 257, in iterencode
    return _iterencode(o, 0)
  File "C:\Users\AARON-PREDATOR\AppData\Local\Programs\Python\Python36\lib\json\encoder.py", line 180, in default
    o.__class__.__name__)
TypeError: Object of type 'Timestamp' is not JSON serializable
[2021-03-27 18:34:16,809][Thread-3:7088][task_id:django.server][basehttp.py:157][ERROR]["GET /analysis/basic/2015-01-01/AMZN HTTP/1.1" 500 136236]
[2021-03-27 18:58:11,094][Thread-6:19608][task_id:django.server][basehttp.py:157][ERROR]["GET /analysis/predict/AMZN HTTP/1.1" 500 59]
[2021-03-27 19:01:59,137][Thread-6:1264][task_id:django.request][log.py:230][ERROR][Internal Server Error: /analysis/predict/AMZN]
Traceback (most recent call last):
  File "D:\Projects\Stock_Trend_Analysis_APP\stock-trend-ana-admin\venv\lib\site-packages\django\core\handlers\exception.py", line 47, in inner
    response = get_response(request)
  File "D:\Projects\Stock_Trend_Analysis_APP\stock-trend-ana-admin\venv\lib\site-packages\django\core\handlers\base.py", line 181, in _get_response
    response = wrapped_callback(request, *callback_args, **callback_kwargs)
  File "D:\Projects\Stock_Trend_Analysis_APP\stock-trend-ana-admin\sta_admin\analysis\views.py", line 65, in predict_future_price
    return JsonResponseResult().ok(data=y_test)
  File "D:\Projects\Stock_Trend_Analysis_APP\stock-trend-ana-admin\sta_admin\common\JsonResponseResult.py", line 23, in ok
    self.__init__(data=data, code=code, msg=msg, **kwargs)
  File "D:\Projects\Stock_Trend_Analysis_APP\stock-trend-ana-admin\sta_admin\common\JsonResponseResult.py", line 10, in __init__
    if not data: data = list()
ValueError: The truth value of an array with more than one element is ambiguous. Use a.any() or a.all()
[2021-03-27 19:01:59,141][Thread-6:1264][task_id:django.server][basehttp.py:157][ERROR]["GET /analysis/predict/AMZN HTTP/1.1" 500 105485]
[2021-03-31 21:00:02,815][Thread-3:9600][task_id:django.request][log.py:230][ERROR][Internal Server Error: /analysis/basic/Mon Apr 01 2019 21:00:02 GMT-0700 (Pacific Daylight Time)/AMZN]
Traceback (most recent call last):
  File "D:\Projects\Stock_Trend_Analysis_APP\stock-trend-ana-admin\venv\lib\site-packages\django\core\handlers\exception.py", line 47, in inner
    response = get_response(request)
  File "D:\Projects\Stock_Trend_Analysis_APP\stock-trend-ana-admin\venv\lib\site-packages\django\core\handlers\base.py", line 181, in _get_response
    response = wrapped_callback(request, *callback_args, **callback_kwargs)
  File "D:\Projects\Stock_Trend_Analysis_APP\stock-trend-ana-admin\sta_admin\analysis\views.py", line 40, in get_basic_info
    start_date_obj = datetime.strptime(start_date, '%Y-%m-%d')
  File "C:\Users\AARON-PREDATOR\AppData\Local\Programs\Python\Python36\lib\_strptime.py", line 565, in _strptime_datetime
    tt, fraction = _strptime(data_string, format)
  File "C:\Users\AARON-PREDATOR\AppData\Local\Programs\Python\Python36\lib\_strptime.py", line 362, in _strptime
    (data_string, format))
ValueError: time data 'Mon Apr 01 2019 21:00:02 GMT-0700 (Pacific Daylight Time)' does not match format '%Y-%m-%d'
[2021-03-31 21:00:02,818][Thread-3:9600][task_id:django.server][basehttp.py:157][ERROR]["GET /analysis/basic/Mon%20Apr%2001%202019%2021:00:02%20GMT-0700%20(Pacific%20Daylight%20Time)/AMZN HTTP/1.1" 500 86963]
[2021-04-03 19:28:51,601][Thread-1:3712][task_id:django.request][log.py:230][ERROR][Internal Server Error: /analysis/candle/2015-01-01/AMZN]
Traceback (most recent call last):
  File "D:\Projects\Stock_Trend_Analysis_APP\stock-trend-ana-admin\venv\lib\site-packages\pandas\core\indexes\base.py", line 2898, in get_loc
    return self._engine.get_loc(casted_key)
  File "pandas\_libs\index.pyx", line 70, in pandas._libs.index.IndexEngine.get_loc
  File "pandas\_libs\index.pyx", line 101, in pandas._libs.index.IndexEngine.get_loc
  File "pandas\_libs\hashtable_class_helper.pxi", line 1675, in pandas._libs.hashtable.PyObjectHashTable.get_item
  File "pandas\_libs\hashtable_class_helper.pxi", line 1683, in pandas._libs.hashtable.PyObjectHashTable.get_item
KeyError: ('Open', 'Close', 'Low', 'High')

The above exception was the direct cause of the following exception:

Traceback (most recent call last):
  File "D:\Projects\Stock_Trend_Analysis_APP\stock-trend-ana-admin\venv\lib\site-packages\django\core\handlers\exception.py", line 47, in inner
    response = get_response(request)
  File "D:\Projects\Stock_Trend_Analysis_APP\stock-trend-ana-admin\venv\lib\site-packages\django\core\handlers\base.py", line 181, in _get_response
    response = wrapped_callback(request, *callback_args, **callback_kwargs)
  File "D:\Projects\Stock_Trend_Analysis_APP\stock-trend-ana-admin\sta_admin\analysis\views.py", line 74, in get_candle_render_data
    data_obj = generator.download_and_wrap_basic_info()
  File "D:\Projects\Stock_Trend_Analysis_APP\stock-trend-ana-admin\sta_admin\common\StockDataGenerator.py", line 81, in download_and_wrap_basic_info
    result['values'] = data['Open', 'Close', 'Low', 'High'].tolist()
  File "D:\Projects\Stock_Trend_Analysis_APP\stock-trend-ana-admin\venv\lib\site-packages\pandas\core\frame.py", line 2906, in __getitem__
    indexer = self.columns.get_loc(key)
  File "D:\Projects\Stock_Trend_Analysis_APP\stock-trend-ana-admin\venv\lib\site-packages\pandas\core\indexes\base.py", line 2900, in get_loc
    raise KeyError(key) from err
KeyError: ('Open', 'Close', 'Low', 'High')
[2021-04-03 19:28:51,608][Thread-1:3712][task_id:django.server][basehttp.py:157][ERROR]["GET /analysis/candle/2015-01-01/AMZN HTTP/1.1" 500 153684]
[2021-04-03 19:30:22,624][Thread-1:8396][task_id:django.request][log.py:230][ERROR][Internal Server Error: /analysis/candle/2015-01-01/AMZN]
Traceback (most recent call last):
  File "D:\Projects\Stock_Trend_Analysis_APP\stock-trend-ana-admin\venv\lib\site-packages\django\core\handlers\exception.py", line 47, in inner
    response = get_response(request)
  File "D:\Projects\Stock_Trend_Analysis_APP\stock-trend-ana-admin\venv\lib\site-packages\django\core\handlers\base.py", line 181, in _get_response
    response = wrapped_callback(request, *callback_args, **callback_kwargs)
  File "D:\Projects\Stock_Trend_Analysis_APP\stock-trend-ana-admin\sta_admin\analysis\views.py", line 74, in get_candle_render_data
    data_obj = generator.download_and_wrap_basic_info()
  File "D:\Projects\Stock_Trend_Analysis_APP\stock-trend-ana-admin\sta_admin\common\StockDataGenerator.py", line 81, in download_and_wrap_basic_info
    result['values'] = data[['Open', 'Close', 'Low', 'High']].tolist()
  File "D:\Projects\Stock_Trend_Analysis_APP\stock-trend-ana-admin\venv\lib\site-packages\pandas\core\generic.py", line 5141, in __getattr__
    return object.__getattribute__(self, name)
AttributeError: 'DataFrame' object has no attribute 'tolist'
[2021-04-03 19:30:22,631][Thread-1:8396][task_id:django.server][basehttp.py:157][ERROR]["GET /analysis/candle/2015-01-01/AMZN HTTP/1.1" 500 94179]
[2021-04-04 01:36:57,769][Thread-1:13012][task_id:django.request][log.py:230][ERROR][Internal Server Error: /analysis/predict/AMZN]
Traceback (most recent call last):
  File "D:\Projects\Stock_Trend_Analysis_APP\stock-trend-ana-admin\venv\lib\site-packages\django\core\handlers\exception.py", line 47, in inner
    response = get_response(request)
  File "D:\Projects\Stock_Trend_Analysis_APP\stock-trend-ana-admin\venv\lib\site-packages\django\core\handlers\base.py", line 181, in _get_response
    response = wrapped_callback(request, *callback_args, **callback_kwargs)
  File "D:\Projects\Stock_Trend_Analysis_APP\stock-trend-ana-admin\sta_admin\analysis\views.py", line 97, in predict_future_price
    return JsonResponseResult().ok(data=result)
  File "D:\Projects\Stock_Trend_Analysis_APP\stock-trend-ana-admin\sta_admin\common\JsonResponseResult.py", line 23, in ok
    self.__init__(data=data, code=code, msg=msg, **kwargs)
  File "D:\Projects\Stock_Trend_Analysis_APP\stock-trend-ana-admin\sta_admin\common\JsonResponseResult.py", line 14, in __init__
    super().__init__(content=json.dumps(self.data), **kwargs)
  File "C:\Users\AARON-PREDATOR\AppData\Local\Programs\Python\Python36\lib\json\__init__.py", line 231, in dumps
    return _default_encoder.encode(obj)
  File "C:\Users\AARON-PREDATOR\AppData\Local\Programs\Python\Python36\lib\json\encoder.py", line 199, in encode
    chunks = self.iterencode(o, _one_shot=True)
  File "C:\Users\AARON-PREDATOR\AppData\Local\Programs\Python\Python36\lib\json\encoder.py", line 257, in iterencode
    return _iterencode(o, 0)
  File "C:\Users\AARON-PREDATOR\AppData\Local\Programs\Python\Python36\lib\json\encoder.py", line 180, in default
    o.__class__.__name__)
TypeError: Object of type 'recarray' is not JSON serializable
[2021-04-04 01:36:57,774][Thread-1:13012][task_id:django.server][basehttp.py:157][ERROR]["GET /analysis/predict/AMZN HTTP/1.1" 500 140096]
[2021-04-12 05:34:50,027][Thread-83:22672][task_id:django.request][log.py:230][ERROR][Internal Server Error: /analysis/candle/2015-01-01/AMZN]
Traceback (most recent call last):
  File "D:\Projects\Stock_Trend_Analysis_APP\stock-trend-ana-admin\sta_admin\common\StockDataGenerator.py", line 82, in download_and_wrap_basic_info
    rawdata = yf.download([self._stock.get_ticker()], start=self._stock.get_start_date(), end=end_date)[
  File "D:\Projects\Stock_Trend_Analysis_APP\stock-trend-ana-admin\venv\lib\site-packages\yfinance\multi.py", line 109, in download
    shared._PROGRESS_BAR.completed()
  File "D:\Projects\Stock_Trend_Analysis_APP\stock-trend-ana-admin\venv\lib\site-packages\yfinance\utils.py", line 185, in completed
    print('\r' + str(self), end='')
OSError: [Errno 22] Invalid argument

During handling of the above exception, another exception occurred:

Traceback (most recent call last):
  File "D:\Projects\Stock_Trend_Analysis_APP\stock-trend-ana-admin\venv\lib\site-packages\django\core\handlers\exception.py", line 47, in inner
    response = get_response(request)
  File "D:\Projects\Stock_Trend_Analysis_APP\stock-trend-ana-admin\venv\lib\site-packages\django\core\handlers\base.py", line 181, in _get_response
    response = wrapped_callback(request, *callback_args, **callback_kwargs)
  File "D:\Projects\Stock_Trend_Analysis_APP\stock-trend-ana-admin\sta_admin\analysis\views.py", line 74, in get_candle_render_data
    data_obj = generator.download_and_wrap_basic_info()
  File "D:\Projects\Stock_Trend_Analysis_APP\stock-trend-ana-admin\sta_admin\common\StockDataGenerator.py", line 115, in download_and_wrap_basic_info
    print("Download Data Failed, Since some unknown reason.")
OSError: [Errno 22] Invalid argument
[2021-04-12 05:34:50,033][Thread-83:22672][task_id:django.server][basehttp.py:157][ERROR]["GET /analysis/candle/2015-01-01/AMZN HTTP/1.1" 500 100270]
[2021-04-12 05:35:25,460][Thread-83:22672][task_id:django.request][log.py:230][ERROR][Internal Server Error: /analysis/candle/2015-01-01/AMZN]
Traceback (most recent call last):
  File "D:\Projects\Stock_Trend_Analysis_APP\stock-trend-ana-admin\sta_admin\common\StockDataGenerator.py", line 82, in download_and_wrap_basic_info
    rawdata = yf.download([self._stock.get_ticker()], start=self._stock.get_start_date(), end=end_date)[
  File "D:\Projects\Stock_Trend_Analysis_APP\stock-trend-ana-admin\venv\lib\site-packages\yfinance\multi.py", line 109, in download
    shared._PROGRESS_BAR.completed()
  File "D:\Projects\Stock_Trend_Analysis_APP\stock-trend-ana-admin\venv\lib\site-packages\yfinance\utils.py", line 185, in completed
    print('\r' + str(self), end='')
OSError: [Errno 22] Invalid argument

During handling of the above exception, another exception occurred:

Traceback (most recent call last):
  File "D:\Projects\Stock_Trend_Analysis_APP\stock-trend-ana-admin\venv\lib\site-packages\django\core\handlers\exception.py", line 47, in inner
    response = get_response(request)
  File "D:\Projects\Stock_Trend_Analysis_APP\stock-trend-ana-admin\venv\lib\site-packages\django\core\handlers\base.py", line 181, in _get_response
    response = wrapped_callback(request, *callback_args, **callback_kwargs)
  File "D:\Projects\Stock_Trend_Analysis_APP\stock-trend-ana-admin\sta_admin\analysis\views.py", line 74, in get_candle_render_data
    data_obj = generator.download_and_wrap_basic_info()
  File "D:\Projects\Stock_Trend_Analysis_APP\stock-trend-ana-admin\sta_admin\common\StockDataGenerator.py", line 115, in download_and_wrap_basic_info
    print("Download Data Failed, Since some unknown reason.")
OSError: [Errno 22] Invalid argument
[2021-04-12 05:35:25,463][Thread-83:22672][task_id:django.server][basehttp.py:157][ERROR]["GET /analysis/candle/2015-01-01/AMZN HTTP/1.1" 500 100407]
[2021-04-12 05:36:51,354][Thread-83:22672][task_id:django.request][log.py:230][ERROR][Internal Server Error: /analysis/candle/2015-01-01/AMZN]
Traceback (most recent call last):
  File "D:\Projects\Stock_Trend_Analysis_APP\stock-trend-ana-admin\sta_admin\common\StockDataGenerator.py", line 82, in download_and_wrap_basic_info
    rawdata = yf.download([self._stock.get_ticker()], start=self._stock.get_start_date(), end=end_date)[
  File "D:\Projects\Stock_Trend_Analysis_APP\stock-trend-ana-admin\venv\lib\site-packages\yfinance\multi.py", line 109, in download
    shared._PROGRESS_BAR.completed()
  File "D:\Projects\Stock_Trend_Analysis_APP\stock-trend-ana-admin\venv\lib\site-packages\yfinance\utils.py", line 185, in completed
    print('\r' + str(self), end='')
OSError: [Errno 22] Invalid argument

During handling of the above exception, another exception occurred:

Traceback (most recent call last):
  File "D:\Projects\Stock_Trend_Analysis_APP\stock-trend-ana-admin\venv\lib\site-packages\django\core\handlers\exception.py", line 47, in inner
    response = get_response(request)
  File "D:\Projects\Stock_Trend_Analysis_APP\stock-trend-ana-admin\venv\lib\site-packages\django\core\handlers\base.py", line 181, in _get_response
    response = wrapped_callback(request, *callback_args, **callback_kwargs)
  File "D:\Projects\Stock_Trend_Analysis_APP\stock-trend-ana-admin\sta_admin\analysis\views.py", line 74, in get_candle_render_data
    data_obj = generator.download_and_wrap_basic_info()
  File "D:\Projects\Stock_Trend_Analysis_APP\stock-trend-ana-admin\sta_admin\common\StockDataGenerator.py", line 115, in download_and_wrap_basic_info
    print("Download Data Failed, Since some unknown reason.")
OSError: [Errno 22] Invalid argument
[2021-04-12 05:36:51,356][Thread-83:22672][task_id:django.server][basehttp.py:157][ERROR]["GET /analysis/candle/2015-01-01/AMZN HTTP/1.1" 500 100407]
[2021-04-12 05:37:03,082][Thread-83:22672][task_id:django.request][log.py:230][ERROR][Internal Server Error: /analysis/basic/2015-01-01/AMZN]
Traceback (most recent call last):
  File "D:\Projects\Stock_Trend_Analysis_APP\stock-trend-ana-admin\sta_admin\common\StockDataGenerator.py", line 42, in download_basic_info
    rawdata = yf.download([self._stock.get_ticker()], start=self._stock.get_start_date(), end=end_date)[
  File "D:\Projects\Stock_Trend_Analysis_APP\stock-trend-ana-admin\venv\lib\site-packages\yfinance\multi.py", line 109, in download
    shared._PROGRESS_BAR.completed()
  File "D:\Projects\Stock_Trend_Analysis_APP\stock-trend-ana-admin\venv\lib\site-packages\yfinance\utils.py", line 185, in completed
    print('\r' + str(self), end='')
OSError: [Errno 22] Invalid argument

During handling of the above exception, another exception occurred:

Traceback (most recent call last):
  File "D:\Projects\Stock_Trend_Analysis_APP\stock-trend-ana-admin\venv\lib\site-packages\django\core\handlers\exception.py", line 47, in inner
    response = get_response(request)
  File "D:\Projects\Stock_Trend_Analysis_APP\stock-trend-ana-admin\venv\lib\site-packages\django\core\handlers\base.py", line 181, in _get_response
    response = wrapped_callback(request, *callback_args, **callback_kwargs)
  File "D:\Projects\Stock_Trend_Analysis_APP\stock-trend-ana-admin\sta_admin\analysis\views.py", line 46, in get_basic_info
    _, data_items = generator.download_basic_info()
  File "D:\Projects\Stock_Trend_Analysis_APP\stock-trend-ana-admin\sta_admin\common\StockDataGenerator.py", line 57, in download_basic_info
    print("Download Data Failed, Since some unknown reason.")
OSError: [Errno 22] Invalid argument
[2021-04-12 05:37:03,085][Thread-83:22672][task_id:django.server][basehttp.py:157][ERROR]["GET /analysis/basic/2015-01-01/AMZN HTTP/1.1" 500 99594]
[2021-04-12 05:38:09,339][Thread-91:14924][task_id:django.request][log.py:230][ERROR][Internal Server Error: /analysis/basic/2015-01-01/AMZN]
Traceback (most recent call last):
  File "D:\Projects\Stock_Trend_Analysis_APP\stock-trend-ana-admin\sta_admin\common\StockDataGenerator.py", line 42, in download_basic_info
    rawdata = yf.download([self._stock.get_ticker()], start=self._stock.get_start_date(), end=end_date)[
  File "D:\Projects\Stock_Trend_Analysis_APP\stock-trend-ana-admin\venv\lib\site-packages\yfinance\multi.py", line 109, in download
    shared._PROGRESS_BAR.completed()
  File "D:\Projects\Stock_Trend_Analysis_APP\stock-trend-ana-admin\venv\lib\site-packages\yfinance\utils.py", line 185, in completed
    print('\r' + str(self), end='')
OSError: [Errno 22] Invalid argument

During handling of the above exception, another exception occurred:

Traceback (most recent call last):
  File "D:\Projects\Stock_Trend_Analysis_APP\stock-trend-ana-admin\venv\lib\site-packages\django\core\handlers\exception.py", line 47, in inner
    response = get_response(request)
  File "D:\Projects\Stock_Trend_Analysis_APP\stock-trend-ana-admin\venv\lib\site-packages\django\core\handlers\base.py", line 181, in _get_response
    response = wrapped_callback(request, *callback_args, **callback_kwargs)
  File "D:\Projects\Stock_Trend_Analysis_APP\stock-trend-ana-admin\sta_admin\analysis\views.py", line 46, in get_basic_info
    _, data_items = generator.download_basic_info()
  File "D:\Projects\Stock_Trend_Analysis_APP\stock-trend-ana-admin\sta_admin\common\StockDataGenerator.py", line 57, in download_basic_info
    print("Download Data Failed, Since some unknown reason.")
OSError: [Errno 22] Invalid argument
[2021-04-12 05:38:09,340][Thread-91:14924][task_id:django.server][basehttp.py:157][ERROR]["GET /analysis/basic/2015-01-01/AMZN HTTP/1.1" 500 98133]
[2021-04-12 05:39:26,094][Thread-94:18276][task_id:django.request][log.py:230][ERROR][Internal Server Error: /analysis/candle/2015-01-01/AMZN]
Traceback (most recent call last):
  File "D:\Projects\Stock_Trend_Analysis_APP\stock-trend-ana-admin\sta_admin\common\StockDataGenerator.py", line 82, in download_and_wrap_basic_info
    rawdata = yf.download([self._stock.get_ticker()], start=self._stock.get_start_date(), end=end_date)[
  File "D:\Projects\Stock_Trend_Analysis_APP\stock-trend-ana-admin\venv\lib\site-packages\yfinance\multi.py", line 109, in download
    shared._PROGRESS_BAR.completed()
  File "D:\Projects\Stock_Trend_Analysis_APP\stock-trend-ana-admin\venv\lib\site-packages\yfinance\utils.py", line 185, in completed
    print('\r' + str(self), end='')
OSError: [Errno 22] Invalid argument

During handling of the above exception, another exception occurred:

Traceback (most recent call last):
  File "D:\Projects\Stock_Trend_Analysis_APP\stock-trend-ana-admin\venv\lib\site-packages\django\core\handlers\exception.py", line 47, in inner
    response = get_response(request)
  File "D:\Projects\Stock_Trend_Analysis_APP\stock-trend-ana-admin\venv\lib\site-packages\django\core\handlers\base.py", line 181, in _get_response
    response = wrapped_callback(request, *callback_args, **callback_kwargs)
  File "D:\Projects\Stock_Trend_Analysis_APP\stock-trend-ana-admin\sta_admin\analysis\views.py", line 74, in get_candle_render_data
    data_obj = generator.download_and_wrap_basic_info()
  File "D:\Projects\Stock_Trend_Analysis_APP\stock-trend-ana-admin\sta_admin\common\StockDataGenerator.py", line 115, in download_and_wrap_basic_info
    print("Download Data Failed, Since some unknown reason.")
OSError: [Errno 22] Invalid argument
[2021-04-12 05:39:26,096][Thread-94:18276][task_id:django.server][basehttp.py:157][ERROR]["GET /analysis/candle/2015-01-01/AMZN HTTP/1.1" 500 100270]
[2021-04-13 06:28:53,446][Thread-1:2928][task_id:django.request][log.py:230][ERROR][Internal Server Error: /analysis/index/latest/TSLA]
Traceback (most recent call last):
  File "D:\Projects\Stock_Trend_Analysis_APP\stock-trend-ana-admin\venv\lib\site-packages\django\core\handlers\exception.py", line 47, in inner
    response = get_response(request)
  File "D:\Projects\Stock_Trend_Analysis_APP\stock-trend-ana-admin\venv\lib\site-packages\django\core\handlers\base.py", line 181, in _get_response
    response = wrapped_callback(request, *callback_args, **callback_kwargs)
  File "D:\Projects\Stock_Trend_Analysis_APP\stock-trend-ana-admin\sta_admin\analysis\views.py", line 133, in get_latest_index
    index_values = read_txt_file(ticker)
  File "D:\Projects\Stock_Trend_Analysis_APP\stock-trend-ana-admin\sta_admin\common\FileUtil.py", line 29, in read_txt_file
    with open(file_path, 'r', encoding='utf-8') as data_file:
FileNotFoundError: [Errno 2] No such file or directory: ''
[2021-04-13 06:28:53,448][Thread-1:2928][task_id:django.server][basehttp.py:157][ERROR]["GET /analysis/index/latest/TSLA HTTP/1.1" 500 78768]
[2021-04-13 07:13:11,631][Thread-3:10520][task_id:django.request][log.py:230][ERROR][Internal Server Error: /analysis/candle/2016-04-14/AMZN]
Traceback (most recent call last):
  File "D:\Projects\Stock_Trend_Analysis_APP\stock-trend-ana-admin\venv\lib\site-packages\django\core\handlers\exception.py", line 47, in inner
    response = get_response(request)
  File "D:\Projects\Stock_Trend_Analysis_APP\stock-trend-ana-admin\venv\lib\site-packages\django\core\handlers\base.py", line 181, in _get_response
    response = wrapped_callback(request, *callback_args, **callback_kwargs)
  File "D:\Projects\Stock_Trend_Analysis_APP\stock-trend-ana-admin\sta_admin\analysis\views.py", line 100, in get_candle_render_data
    metadata = StockMetaData(ticker, start_date_obj)
  File "D:\Projects\Stock_Trend_Analysis_APP\stock-trend-ana-admin\sta_admin\common\StockMetaData.py", line 20, in __init__
    AVAILABLE_TOKEN = check_is_subset(TOKEN, os.getcwd() + DATA_SAVED_PLACE)
  File "D:\Projects\Stock_Trend_Analysis_APP\stock-trend-ana-admin\sta_admin\common\StringUtil.py", line 19, in check_is_subset
    f_ticker, f_start, f_end = file.split("_")
ValueError: not enough values to unpack (expected 3, got 2)
[2021-04-13 07:13:11,633][Thread-3:10520][task_id:django.server][basehttp.py:157][ERROR]["GET /analysis/candle/2016-04-14/AMZN HTTP/1.1" 500 89274]
[2021-04-13 07:13:59,444][Thread-3:10520][task_id:django.request][log.py:230][ERROR][Internal Server Error: /analysis/candle/2015-01-01/AMZN]
Traceback (most recent call last):
  File "D:\Projects\Stock_Trend_Analysis_APP\stock-trend-ana-admin\venv\lib\site-packages\django\core\handlers\exception.py", line 47, in inner
    response = get_response(request)
  File "D:\Projects\Stock_Trend_Analysis_APP\stock-trend-ana-admin\venv\lib\site-packages\django\core\handlers\base.py", line 181, in _get_response
    response = wrapped_callback(request, *callback_args, **callback_kwargs)
  File "D:\Projects\Stock_Trend_Analysis_APP\stock-trend-ana-admin\sta_admin\analysis\views.py", line 100, in get_candle_render_data
    metadata = StockMetaData(ticker, start_date_obj)
  File "D:\Projects\Stock_Trend_Analysis_APP\stock-trend-ana-admin\sta_admin\common\StockMetaData.py", line 20, in __init__
    AVAILABLE_TOKEN = check_is_subset(TOKEN, os.getcwd() + DATA_SAVED_PLACE)
  File "D:\Projects\Stock_Trend_Analysis_APP\stock-trend-ana-admin\sta_admin\common\StringUtil.py", line 19, in check_is_subset
    f_ticker, f_start, f_end = file.split("_")
ValueError: not enough values to unpack (expected 3, got 2)
[2021-04-13 07:13:59,445][Thread-3:10520][task_id:django.server][basehttp.py:157][ERROR]["GET /analysis/candle/2015-01-01/AMZN HTTP/1.1" 500 89097]
[2021-04-15 08:54:25,322][Thread-1:14020][task_id:django.request][log.py:230][ERROR][Internal Server Error: /analysis/index/latest/COMP]
Traceback (most recent call last):
  File "D:\Projects\Stock_Trend_Analysis_APP\stock-trend-ana-admin\venv\lib\site-packages\django\core\handlers\exception.py", line 47, in inner
    response = get_response(request)
  File "D:\Projects\Stock_Trend_Analysis_APP\stock-trend-ana-admin\venv\lib\site-packages\django\core\handlers\base.py", line 181, in _get_response
    response = wrapped_callback(request, *callback_args, **callback_kwargs)
  File "D:\Projects\Stock_Trend_Analysis_APP\stock-trend-ana-admin\sta_admin\analysis\views.py", line 133, in get_latest_index
    index_values = read_txt_file(ticker)
  File "D:\Projects\Stock_Trend_Analysis_APP\stock-trend-ana-admin\sta_admin\common\FileUtil.py", line 38, in read_txt_file
    json_line = json.loads(line)
  File "C:\Users\AARON-PREDATOR\AppData\Local\Programs\Python\Python36\lib\json\__init__.py", line 354, in loads
    return _default_decoder.decode(s)
  File "C:\Users\AARON-PREDATOR\AppData\Local\Programs\Python\Python36\lib\json\decoder.py", line 339, in decode
    obj, end = self.raw_decode(s, idx=_w(s, 0).end())
  File "C:\Users\AARON-PREDATOR\AppData\Local\Programs\Python\Python36\lib\json\decoder.py", line 357, in raw_decode
    raise JSONDecodeError("Expecting value", s, err.value) from None
json.decoder.JSONDecodeError: Expecting value: line 2 column 1 (char 1)
[2021-04-15 08:54:25,328][Thread-2:20768][task_id:django.request][log.py:230][ERROR][Internal Server Error: /analysis/index/latest/SP500]
Traceback (most recent call last):
  File "D:\Projects\Stock_Trend_Analysis_APP\stock-trend-ana-admin\venv\lib\site-packages\django\core\handlers\exception.py", line 47, in inner
    response = get_response(request)
  File "D:\Projects\Stock_Trend_Analysis_APP\stock-trend-ana-admin\venv\lib\site-packages\django\core\handlers\base.py", line 181, in _get_response
    response = wrapped_callback(request, *callback_args, **callback_kwargs)
  File "D:\Projects\Stock_Trend_Analysis_APP\stock-trend-ana-admin\sta_admin\analysis\views.py", line 133, in get_latest_index
    index_values = read_txt_file(ticker)
  File "D:\Projects\Stock_Trend_Analysis_APP\stock-trend-ana-admin\sta_admin\common\FileUtil.py", line 38, in read_txt_file
    json_line = json.loads(line)
  File "C:\Users\AARON-PREDATOR\AppData\Local\Programs\Python\Python36\lib\json\__init__.py", line 354, in loads
    return _default_decoder.decode(s)
  File "C:\Users\AARON-PREDATOR\AppData\Local\Programs\Python\Python36\lib\json\decoder.py", line 339, in decode
    obj, end = self.raw_decode(s, idx=_w(s, 0).end())
  File "C:\Users\AARON-PREDATOR\AppData\Local\Programs\Python\Python36\lib\json\decoder.py", line 357, in raw_decode
    raise JSONDecodeError("Expecting value", s, err.value) from None
json.decoder.JSONDecodeError: Expecting value: line 2 column 1 (char 1)
[2021-04-15 08:54:25,332][Thread-2:20768][task_id:django.server][basehttp.py:157][ERROR]["GET /analysis/index/latest/SP500 HTTP/1.1" 500 113147]
[2021-04-15 08:54:25,333][Thread-1:14020][task_id:django.server][basehttp.py:157][ERROR]["GET /analysis/index/latest/COMP HTTP/1.1" 500 112708]
[2021-04-15 08:54:30,698][Thread-2:20768][task_id:django.request][log.py:230][ERROR][Internal Server Error: /analysis/index/latest/COMP]
Traceback (most recent call last):
  File "D:\Projects\Stock_Trend_Analysis_APP\stock-trend-ana-admin\venv\lib\site-packages\django\core\handlers\exception.py", line 47, in inner
    response = get_response(request)
  File "D:\Projects\Stock_Trend_Analysis_APP\stock-trend-ana-admin\venv\lib\site-packages\django\core\handlers\base.py", line 181, in _get_response
    response = wrapped_callback(request, *callback_args, **callback_kwargs)
  File "D:\Projects\Stock_Trend_Analysis_APP\stock-trend-ana-admin\sta_admin\analysis\views.py", line 133, in get_latest_index
    index_values = read_txt_file(ticker)
  File "D:\Projects\Stock_Trend_Analysis_APP\stock-trend-ana-admin\sta_admin\common\FileUtil.py", line 38, in read_txt_file
    json_line = json.loads(line)
  File "C:\Users\AARON-PREDATOR\AppData\Local\Programs\Python\Python36\lib\json\__init__.py", line 354, in loads
    return _default_decoder.decode(s)
  File "C:\Users\AARON-PREDATOR\AppData\Local\Programs\Python\Python36\lib\json\decoder.py", line 339, in decode
    obj, end = self.raw_decode(s, idx=_w(s, 0).end())
  File "C:\Users\AARON-PREDATOR\AppData\Local\Programs\Python\Python36\lib\json\decoder.py", line 357, in raw_decode
    raise JSONDecodeError("Expecting value", s, err.value) from None
json.decoder.JSONDecodeError: Expecting value: line 2 column 1 (char 1)
[2021-04-15 08:54:30,729][Thread-1:14020][task_id:django.request][log.py:230][ERROR][Internal Server Error: /analysis/index/latest/SP500]
Traceback (most recent call last):
  File "D:\Projects\Stock_Trend_Analysis_APP\stock-trend-ana-admin\venv\lib\site-packages\django\core\handlers\exception.py", line 47, in inner
    response = get_response(request)
  File "D:\Projects\Stock_Trend_Analysis_APP\stock-trend-ana-admin\venv\lib\site-packages\django\core\handlers\base.py", line 181, in _get_response
    response = wrapped_callback(request, *callback_args, **callback_kwargs)
  File "D:\Projects\Stock_Trend_Analysis_APP\stock-trend-ana-admin\sta_admin\analysis\views.py", line 133, in get_latest_index
    index_values = read_txt_file(ticker)
  File "D:\Projects\Stock_Trend_Analysis_APP\stock-trend-ana-admin\sta_admin\common\FileUtil.py", line 38, in read_txt_file
    json_line = json.loads(line)
  File "C:\Users\AARON-PREDATOR\AppData\Local\Programs\Python\Python36\lib\json\__init__.py", line 354, in loads
    return _default_decoder.decode(s)
  File "C:\Users\AARON-PREDATOR\AppData\Local\Programs\Python\Python36\lib\json\decoder.py", line 339, in decode
    obj, end = self.raw_decode(s, idx=_w(s, 0).end())
  File "C:\Users\AARON-PREDATOR\AppData\Local\Programs\Python\Python36\lib\json\decoder.py", line 357, in raw_decode
    raise JSONDecodeError("Expecting value", s, err.value) from None
json.decoder.JSONDecodeError: Expecting value: line 2 column 1 (char 1)
[2021-04-15 08:54:30,730][Thread-2:20768][task_id:django.server][basehttp.py:157][ERROR]["GET /analysis/index/latest/COMP HTTP/1.1" 500 112708]
[2021-04-15 08:54:30,732][Thread-1:14020][task_id:django.server][basehttp.py:157][ERROR]["GET /analysis/index/latest/SP500 HTTP/1.1" 500 113147]
[2021-04-15 08:55:46,891][Thread-6:19636][task_id:django.request][log.py:230][ERROR][Internal Server Error: /analysis/index/latest/COMP]
Traceback (most recent call last):
  File "D:\Projects\Stock_Trend_Analysis_APP\stock-trend-ana-admin\venv\lib\site-packages\django\core\handlers\exception.py", line 47, in inner
    response = get_response(request)
  File "D:\Projects\Stock_Trend_Analysis_APP\stock-trend-ana-admin\venv\lib\site-packages\django\core\handlers\base.py", line 181, in _get_response
    response = wrapped_callback(request, *callback_args, **callback_kwargs)
  File "D:\Projects\Stock_Trend_Analysis_APP\stock-trend-ana-admin\sta_admin\analysis\views.py", line 133, in get_latest_index
    index_values = read_txt_file(ticker)
  File "D:\Projects\Stock_Trend_Analysis_APP\stock-trend-ana-admin\sta_admin\common\FileUtil.py", line 38, in read_txt_file
    json_line = json.loads(line)
  File "C:\Users\AARON-PREDATOR\AppData\Local\Programs\Python\Python36\lib\json\__init__.py", line 354, in loads
    return _default_decoder.decode(s)
  File "C:\Users\AARON-PREDATOR\AppData\Local\Programs\Python\Python36\lib\json\decoder.py", line 339, in decode
    obj, end = self.raw_decode(s, idx=_w(s, 0).end())
  File "C:\Users\AARON-PREDATOR\AppData\Local\Programs\Python\Python36\lib\json\decoder.py", line 357, in raw_decode
    raise JSONDecodeError("Expecting value", s, err.value) from None
json.decoder.JSONDecodeError: Expecting value: line 2 column 1 (char 1)
[2021-04-15 08:55:46,898][Thread-6:19636][task_id:django.server][basehttp.py:157][ERROR]["GET /analysis/index/latest/COMP HTTP/1.1" 500 115662]
[2021-04-15 08:55:50,839][Thread-6:19636][task_id:django.request][log.py:230][ERROR][Internal Server Error: /analysis/index/latest/COMP]
Traceback (most recent call last):
  File "D:\Projects\Stock_Trend_Analysis_APP\stock-trend-ana-admin\venv\lib\site-packages\django\core\handlers\exception.py", line 47, in inner
    response = get_response(request)
  File "D:\Projects\Stock_Trend_Analysis_APP\stock-trend-ana-admin\venv\lib\site-packages\django\core\handlers\base.py", line 181, in _get_response
    response = wrapped_callback(request, *callback_args, **callback_kwargs)
  File "D:\Projects\Stock_Trend_Analysis_APP\stock-trend-ana-admin\sta_admin\analysis\views.py", line 133, in get_latest_index
    index_values = read_txt_file(ticker)
  File "D:\Projects\Stock_Trend_Analysis_APP\stock-trend-ana-admin\sta_admin\common\FileUtil.py", line 38, in read_txt_file
    json_line = json.loads(line)
  File "C:\Users\AARON-PREDATOR\AppData\Local\Programs\Python\Python36\lib\json\__init__.py", line 354, in loads
    return _default_decoder.decode(s)
  File "C:\Users\AARON-PREDATOR\AppData\Local\Programs\Python\Python36\lib\json\decoder.py", line 339, in decode
    obj, end = self.raw_decode(s, idx=_w(s, 0).end())
  File "C:\Users\AARON-PREDATOR\AppData\Local\Programs\Python\Python36\lib\json\decoder.py", line 357, in raw_decode
    raise JSONDecodeError("Expecting value", s, err.value) from None
json.decoder.JSONDecodeError: Expecting value: line 2 column 1 (char 1)
[2021-04-15 08:55:50,844][Thread-6:19636][task_id:django.server][basehttp.py:157][ERROR]["GET /analysis/index/latest/COMP HTTP/1.1" 500 115662]
[2021-04-15 08:55:55,749][Thread-6:19636][task_id:django.request][log.py:230][ERROR][Internal Server Error: /analysis/index/latest/COMP]
Traceback (most recent call last):
  File "D:\Projects\Stock_Trend_Analysis_APP\stock-trend-ana-admin\venv\lib\site-packages\django\core\handlers\exception.py", line 47, in inner
    response = get_response(request)
  File "D:\Projects\Stock_Trend_Analysis_APP\stock-trend-ana-admin\venv\lib\site-packages\django\core\handlers\base.py", line 181, in _get_response
    response = wrapped_callback(request, *callback_args, **callback_kwargs)
  File "D:\Projects\Stock_Trend_Analysis_APP\stock-trend-ana-admin\sta_admin\analysis\views.py", line 133, in get_latest_index
    index_values = read_txt_file(ticker)
  File "D:\Projects\Stock_Trend_Analysis_APP\stock-trend-ana-admin\sta_admin\common\FileUtil.py", line 38, in read_txt_file
    json_line = json.loads(line)
  File "C:\Users\AARON-PREDATOR\AppData\Local\Programs\Python\Python36\lib\json\__init__.py", line 354, in loads
    return _default_decoder.decode(s)
  File "C:\Users\AARON-PREDATOR\AppData\Local\Programs\Python\Python36\lib\json\decoder.py", line 339, in decode
    obj, end = self.raw_decode(s, idx=_w(s, 0).end())
  File "C:\Users\AARON-PREDATOR\AppData\Local\Programs\Python\Python36\lib\json\decoder.py", line 357, in raw_decode
    raise JSONDecodeError("Expecting value", s, err.value) from None
json.decoder.JSONDecodeError: Expecting value: line 2 column 1 (char 1)
[2021-04-15 08:55:55,752][Thread-6:19636][task_id:django.server][basehttp.py:157][ERROR]["GET /analysis/index/latest/COMP HTTP/1.1" 500 115662]
[2021-04-15 08:57:14,928][Thread-1:14372][task_id:django.request][log.py:230][ERROR][Internal Server Error: /analysis/index/latest/COMP]
Traceback (most recent call last):
  File "D:\Projects\Stock_Trend_Analysis_APP\stock-trend-ana-admin\venv\lib\site-packages\django\core\handlers\exception.py", line 47, in inner
    response = get_response(request)
  File "D:\Projects\Stock_Trend_Analysis_APP\stock-trend-ana-admin\venv\lib\site-packages\django\core\handlers\base.py", line 181, in _get_response
    response = wrapped_callback(request, *callback_args, **callback_kwargs)
  File "D:\Projects\Stock_Trend_Analysis_APP\stock-trend-ana-admin\sta_admin\analysis\views.py", line 133, in get_latest_index
    index_values = read_txt_file(ticker)
  File "D:\Projects\Stock_Trend_Analysis_APP\stock-trend-ana-admin\sta_admin\common\FileUtil.py", line 38, in read_txt_file
    json_line = json.loads(line)
  File "C:\Users\AARON-PREDATOR\AppData\Local\Programs\Python\Python36\lib\json\__init__.py", line 354, in loads
    return _default_decoder.decode(s)
  File "C:\Users\AARON-PREDATOR\AppData\Local\Programs\Python\Python36\lib\json\decoder.py", line 342, in decode
    raise JSONDecodeError("Extra data", s, end)
json.decoder.JSONDecodeError: Extra data: line 1 column 117 (char 116)
[2021-04-15 08:57:14,931][Thread-1:14372][task_id:django.server][basehttp.py:157][ERROR]["GET /analysis/index/latest/COMP HTTP/1.1" 500 106770]
[2021-04-15 23:03:49,605][Thread-2:1944][task_id:django.request][log.py:230][ERROR][Internal Server Error: /analysis/candle/2016-04-17/AAPL]
Traceback (most recent call last):
  File "D:\Projects\Stock_Trend_Analysis_APP\stock-trend-ana-admin\venv\lib\site-packages\django\core\handlers\exception.py", line 47, in inner
    response = get_response(request)
  File "D:\Projects\Stock_Trend_Analysis_APP\stock-trend-ana-admin\venv\lib\site-packages\django\core\handlers\base.py", line 181, in _get_response
    response = wrapped_callback(request, *callback_args, **callback_kwargs)
  File "D:\Projects\Stock_Trend_Analysis_APP\stock-trend-ana-admin\sta_admin\analysis\views.py", line 100, in get_candle_render_data
    metadata = StockMetaData(ticker, start_date_obj)
  File "D:\Projects\Stock_Trend_Analysis_APP\stock-trend-ana-admin\sta_admin\common\StockMetaData.py", line 20, in __init__
    AVAILABLE_TOKEN = check_is_subset(TOKEN, os.getcwd() + DATA_SAVED_PLACE)
  File "D:\Projects\Stock_Trend_Analysis_APP\stock-trend-ana-admin\sta_admin\common\StringUtil.py", line 19, in check_is_subset
    f_ticker, f_start, f_end = file.split("_")
ValueError: not enough values to unpack (expected 3, got 1)
[2021-04-15 23:03:49,607][Thread-2:1944][task_id:django.server][basehttp.py:157][ERROR]["GET /analysis/candle/2016-04-17/AAPL HTTP/1.1" 500 86883]
[2021-04-15 23:04:07,983][Thread-1:3996][task_id:django.request][log.py:230][ERROR][Internal Server Error: /analysis/candle/2016-04-17/NFLX]
Traceback (most recent call last):
  File "D:\Projects\Stock_Trend_Analysis_APP\stock-trend-ana-admin\venv\lib\site-packages\django\core\handlers\exception.py", line 47, in inner
    response = get_response(request)
  File "D:\Projects\Stock_Trend_Analysis_APP\stock-trend-ana-admin\venv\lib\site-packages\django\core\handlers\base.py", line 181, in _get_response
    response = wrapped_callback(request, *callback_args, **callback_kwargs)
  File "D:\Projects\Stock_Trend_Analysis_APP\stock-trend-ana-admin\sta_admin\analysis\views.py", line 100, in get_candle_render_data
    metadata = StockMetaData(ticker, start_date_obj)
  File "D:\Projects\Stock_Trend_Analysis_APP\stock-trend-ana-admin\sta_admin\common\StockMetaData.py", line 20, in __init__
    AVAILABLE_TOKEN = check_is_subset(TOKEN, os.getcwd() + DATA_SAVED_PLACE)
  File "D:\Projects\Stock_Trend_Analysis_APP\stock-trend-ana-admin\sta_admin\common\StringUtil.py", line 19, in check_is_subset
    f_ticker, f_start, f_end = file.split("_")
ValueError: not enough values to unpack (expected 3, got 1)
[2021-04-15 23:04:07,984][Thread-1:3996][task_id:django.server][basehttp.py:157][ERROR]["GET /analysis/candle/2016-04-17/NFLX HTTP/1.1" 500 86883]
[2021-04-16 04:41:44,136][Thread-1:10424][task_id:django.request][log.py:230][ERROR][Internal Server Error: /analysis/predict/FB]
Traceback (most recent call last):
  File "D:\Projects\Stock_Trend_Analysis_APP\stock-trend-ana-admin\venv\lib\site-packages\django\core\handlers\exception.py", line 47, in inner
    response = get_response(request)
  File "D:\Projects\Stock_Trend_Analysis_APP\stock-trend-ana-admin\venv\lib\site-packages\django\core\handlers\base.py", line 181, in _get_response
    response = wrapped_callback(request, *callback_args, **callback_kwargs)
  File "D:\Projects\Stock_Trend_Analysis_APP\stock-trend-ana-admin\sta_admin\analysis\views.py", line 118, in predict_future_price
    model.load()
  File "D:\Projects\Stock_Trend_Analysis_APP\stock-trend-ana-admin\sta_admin\common\ModelLoader.py", line 29, in load
    os.path.join(os.getcwd() + MODEL_SAVED_PLACE + "/" + self._ticker, MODEL_NAME))
  File "D:\Projects\Stock_Trend_Analysis_APP\stock-trend-ana-admin\venv\lib\site-packages\tensorflow\python\keras\saving\save.py", line 207, in load_model
    compile)
  File "D:\Projects\Stock_Trend_Analysis_APP\stock-trend-ana-admin\venv\lib\site-packages\tensorflow\python\keras\saving\hdf5_format.py", line 200, in load_model_from_hdf5
    training_config, custom_objects))
  File "D:\Projects\Stock_Trend_Analysis_APP\stock-trend-ana-admin\venv\lib\site-packages\tensorflow\python\keras\saving\saving_utils.py", line 224, in compile_args_from_training_config
    metrics = _deserialize_nested_config(_deserialize_metric, metrics_config)
  File "D:\Projects\Stock_Trend_Analysis_APP\stock-trend-ana-admin\venv\lib\site-packages\tensorflow\python\keras\saving\saving_utils.py", line 266, in _deserialize_nested_config
    return [_deserialize_nested_config(deserialize_fn, obj) for obj in config]
  File "D:\Projects\Stock_Trend_Analysis_APP\stock-trend-ana-admin\venv\lib\site-packages\tensorflow\python\keras\saving\saving_utils.py", line 266, in <listcomp>
    return [_deserialize_nested_config(deserialize_fn, obj) for obj in config]
  File "D:\Projects\Stock_Trend_Analysis_APP\stock-trend-ana-admin\venv\lib\site-packages\tensorflow\python\keras\saving\saving_utils.py", line 266, in _deserialize_nested_config
    return [_deserialize_nested_config(deserialize_fn, obj) for obj in config]
  File "D:\Projects\Stock_Trend_Analysis_APP\stock-trend-ana-admin\venv\lib\site-packages\tensorflow\python\keras\saving\saving_utils.py", line 266, in <listcomp>
    return [_deserialize_nested_config(deserialize_fn, obj) for obj in config]
  File "D:\Projects\Stock_Trend_Analysis_APP\stock-trend-ana-admin\venv\lib\site-packages\tensorflow\python\keras\saving\saving_utils.py", line 259, in _deserialize_nested_config
    return deserialize_fn(config)
  File "D:\Projects\Stock_Trend_Analysis_APP\stock-trend-ana-admin\venv\lib\site-packages\tensorflow\python\keras\saving\saving_utils.py", line 289, in _deserialize_metric
    return metrics_module.deserialize(metric_config)
  File "D:\Projects\Stock_Trend_Analysis_APP\stock-trend-ana-admin\venv\lib\site-packages\tensorflow\python\keras\metrics.py", line 3450, in deserialize
    printable_module_name='metric function')
  File "D:\Projects\Stock_Trend_Analysis_APP\stock-trend-ana-admin\venv\lib\site-packages\tensorflow\python\keras\utils\generic_utils.py", line 347, in deserialize_keras_object
    config, module_objects, custom_objects, printable_module_name)
  File "D:\Projects\Stock_Trend_Analysis_APP\stock-trend-ana-admin\venv\lib\site-packages\tensorflow\python\keras\utils\generic_utils.py", line 296, in class_and_config_for_serialized_keras_object
    raise ValueError('Unknown ' + printable_module_name + ': ' + class_name)
ValueError: Unknown metric function: RealMSE
[2021-04-16 04:41:44,141][Thread-1:10424][task_id:django.server][basehttp.py:157][ERROR]["GET /analysis/predict/FB HTTP/1.1" 500 157349]
